package com.MoreOres.blocksitems;

import net.minecraft.block.Block;
import net.minecraft.block.material.Material;
import net.minecraft.client.renderer.texture.IIconRegister;
import net.minecraft.entity.player.EntityPlayer;
import net.minecraft.init.Blocks;
import net.minecraft.world.World;

public class GigaHouse extends Block
{
  public GigaHouse(Material mat)
  {
    super(mat);
    this.setCreativeTab(BlocksandItems.moreOresTab);
  }

  public boolean onBlockActivated(World world, int i, int j, int k, EntityPlayer entity, int p_149727_6_, float p_149727_7_, float p_149727_8_, float p_149727_9_)
  {
    world.setBlock(i + 0, j + 0, k + 0, Blocks.grass);
    world.setBlock(i + -1, j + 0, k + 0, Blocks.grass);
    world.setBlock(i + -1, j + 0, k + 1, Blocks.grass);
    world.setBlock(i + -1, j + 0, k + 2, Blocks.grass);
    world.setBlock(i + -1, j + 0, k + 3, Blocks.grass);
    world.setBlock(i + -1, j + 0, k + 4, Blocks.grass);
    world.setBlock(i + -1, j + 0, k + 5, Blocks.grass);
    world.setBlock(i + -1, j + 0, k + 6, Blocks.grass);
    world.setBlock(i + -1, j + 0, k + 7, Blocks.grass);
    world.setBlock(i + -1, j + 0, k + 8, Blocks.grass);
    world.setBlock(i + -1, j + 0, k + 9, Blocks.grass);
    world.setBlock(i + -1, j + 0, k + 10, Blocks.grass);
    world.setBlock(i + -1, j + 0, k + 11, Blocks.grass);
    world.setBlock(i + -1, j + 0, k + 12, Blocks.grass);

    world.setBlock(i + -1, j + 1, k + 0, Blocks.fence);
    world.setBlock(i + -1, j + 1, k + 1, Blocks.fence);
    world.setBlock(i + -1, j + 1, k + 2, Blocks.fence);
    world.setBlock(i + -1, j + 1, k + 3, Blocks.fence);
    world.setBlock(i + -1, j + 1, k + 4, Blocks.fence);
    world.setBlock(i + -1, j + 1, k + 5, Blocks.fence);
    world.setBlock(i + -1, j + 1, k + 6, Blocks.fence);
    world.setBlock(i + -1, j + 1, k + 7, Blocks.fence);
    world.setBlock(i + -1, j + 1, k + 8, Blocks.fence);
    world.setBlock(i + -1, j + 1, k + 9, Blocks.fence);
    world.setBlock(i + -1, j + 1, k + 10, Blocks.fence);
    world.setBlock(i + -1, j + 1, k + 11, Blocks.fence);
    world.setBlock(i + -1, j + 1, k + 12, Blocks.fence);

    world.setBlock(i + 0, j + 0, k + 5, Blocks.planks, 2, 0);
    world.setBlock(i + 0, j + 0, k + 6, Blocks.farmland, 7, 0);
    world.setBlock(i + 0, j + 0, k + 7, Blocks.farmland, 7, 0);
    world.setBlock(i + 0, j + 0, k + 9, Blocks.farmland, 7, 0);
    world.setBlock(i + 0, j + 0, k + 10, Blocks.farmland, 7, 0);
    world.setBlock(i + 1, j + 0, k + 10, Blocks.potatoes, 7, 0);
    world.setBlock(i + 0, j + 0, k + 11, Blocks.planks, 2, 0);
    world.setBlock(i + 0, j + 0, k + 12, Blocks.grass);
    world.setBlock(i + 0, j + 0, k + 13, Blocks.dirt);
    world.setBlock(i + 0, j + 0, k + 14, Blocks.dirt);
    world.setBlock(i + 0, j + 0, k + 15, Blocks.dirt);
    world.setBlock(i + 0, j + 0, k + 16, Blocks.dirt);
    world.setBlock(i + 0, j + 0, k + 17, Blocks.dirt);
    world.setBlock(i + 0, j + 0, k + 18, Blocks.dirt);
    world.setBlock(i + 0, j + 0, k + 19, Blocks.dirt);
    world.setBlock(i + 0, j + 0, k + 20, Blocks.dirt);
    world.setBlock(i + 0, j + 0, k + 21, Blocks.dirt);
    world.setBlock(i + 0, j + 0, k + 22, Blocks.dirt);
    world.setBlock(i + 0, j + 0, k + 23, Blocks.dirt);
    world.setBlock(i + 0, j + 0, k + 24, Blocks.dirt);
    world.setBlock(i + 0, j + 0, k + 25, Blocks.dirt);
    world.setBlock(i + 0, j + 0, k + 26, Blocks.grass);
    world.setBlock(i + 0, j + 0, k + 27, Blocks.grass);
    world.setBlock(i + 0, j + 0, k + 28, Blocks.stonebrick);
    world.setBlock(i + 0, j + 1, k + 0, Blocks.fence);
    world.setBlock(i + 0, j + 1, k + 6, Blocks.carrots, 5, 0);
    world.setBlock(i + 0, j + 1, k + 7, Blocks.carrots, 3, 0);
    world.setBlock(i + 0, j + 1, k + 9, Blocks.potatoes, 3, 0);
    world.setBlock(i + 0, j + 1, k + 13, Blocks.cobblestone);
    world.setBlock(i + 0, j + 1, k + 14, Blocks.planks, 2, 0);
    world.setBlock(i + 0, j + 1, k + 15, Blocks.planks, 2, 0);
    world.setBlock(i + 0, j + 1, k + 16, Blocks.cobblestone);
    world.setBlock(i + 0, j + 1, k + 17, Blocks.planks, 2, 0);
    world.setBlock(i + 0, j + 1, k + 18, Blocks.planks, 2, 0);
    world.setBlock(i + 0, j + 1, k + 19, Blocks.cobblestone);
    world.setBlock(i + 0, j + 1, k + 20, Blocks.planks, 2, 0);
    world.setBlock(i + 0, j + 1, k + 21, Blocks.planks, 2, 0);
    world.setBlock(i + 0, j + 1, k + 22, Blocks.cobblestone);
    world.setBlock(i + 0, j + 1, k + 23, Blocks.planks, 2, 0);
    world.setBlock(i + 0, j + 1, k + 24, Blocks.planks, 2, 0);
    world.setBlock(i + 0, j + 1, k + 25, Blocks.cobblestone);
    world.setBlock(i + 0, j + 1, k + 26, Blocks.leaves, 5, 0);
    world.setBlock(i + 0, j + 2, k + 13, Blocks.cobblestone);
    world.setBlock(i + 0, j + 2, k + 14, Blocks.planks, 2, 0);
    world.setBlock(i + 0, j + 2, k + 15, Blocks.planks, 2, 0);
    world.setBlock(i + 0, j + 2, k + 16, Blocks.cobblestone);
    world.setBlock(i + 0, j + 2, k + 17, Blocks.planks, 2, 0);
    world.setBlock(i + 0, j + 2, k + 18, Blocks.planks, 2, 0);
    world.setBlock(i + 0, j + 2, k + 19, Blocks.cobblestone);
    world.setBlock(i + 0, j + 2, k + 20, Blocks.planks, 2, 0);
    world.setBlock(i + 0, j + 2, k + 21, Blocks.planks, 2, 0);
    world.setBlock(i + 0, j + 2, k + 22, Blocks.cobblestone);
    world.setBlock(i + 0, j + 2, k + 23, Blocks.planks, 2, 0);
    world.setBlock(i + 0, j + 2, k + 24, Blocks.planks, 2, 0);
    world.setBlock(i + 0, j + 2, k + 25, Blocks.cobblestone);
    world.setBlock(i + 0, j + 3, k + 13, Blocks.cobblestone);
    world.setBlock(i + 0, j + 3, k + 14, Blocks.planks, 2, 0);
    world.setBlock(i + 0, j + 3, k + 15, Blocks.planks, 2, 0);
    world.setBlock(i + 0, j + 3, k + 16, Blocks.cobblestone);
    world.setBlock(i + 0, j + 3, k + 17, Blocks.planks, 2, 0);
    world.setBlock(i + 0, j + 3, k + 18, Blocks.planks, 2, 0);
    world.setBlock(i + 0, j + 3, k + 19, Blocks.cobblestone);
    world.setBlock(i + 0, j + 3, k + 20, Blocks.planks, 2, 0);
    world.setBlock(i + 0, j + 3, k + 21, Blocks.planks, 2, 0);
    world.setBlock(i + 0, j + 3, k + 22, Blocks.cobblestone);
    world.setBlock(i + 0, j + 3, k + 23, Blocks.planks, 2, 0);
    world.setBlock(i + 0, j + 3, k + 24, Blocks.planks, 2, 0);
    world.setBlock(i + 0, j + 3, k + 25, Blocks.cobblestone);
    world.setBlock(i + 0, j + 4, k + 13, Blocks.cobblestone);
    world.setBlock(i + 0, j + 4, k + 14, Blocks.planks, 2, 0);
    world.setBlock(i + 0, j + 4, k + 15, Blocks.planks, 2, 0);
    world.setBlock(i + 0, j + 4, k + 16, Blocks.cobblestone);
    world.setBlock(i + 0, j + 4, k + 17, Blocks.planks, 2, 0);
    world.setBlock(i + 0, j + 4, k + 18, Blocks.planks, 2, 0);
    world.setBlock(i + 0, j + 4, k + 19, Blocks.cobblestone);
    world.setBlock(i + 0, j + 4, k + 20, Blocks.planks, 2, 0);
    world.setBlock(i + 0, j + 4, k + 21, Blocks.planks, 2, 0);
    world.setBlock(i + 0, j + 4, k + 22, Blocks.cobblestone);
    world.setBlock(i + 0, j + 4, k + 23, Blocks.planks, 2, 0);
    world.setBlock(i + 0, j + 4, k + 24, Blocks.planks, 2, 0);
    world.setBlock(i + 0, j + 4, k + 25, Blocks.cobblestone);
    world.setBlock(i + 0, j + 5, k + 13, Blocks.cobblestone);
    world.setBlock(i + 0, j + 5, k + 14, Blocks.planks, 2, 0);
    world.setBlock(i + 0, j + 5, k + 15, Blocks.planks, 2, 0);
    world.setBlock(i + 0, j + 5, k + 16, Blocks.cobblestone);
    world.setBlock(i + 0, j + 5, k + 17, Blocks.planks, 2, 0);
    world.setBlock(i + 0, j + 5, k + 18, Blocks.planks, 2, 0);
    world.setBlock(i + 0, j + 5, k + 19, Blocks.cobblestone);
    world.setBlock(i + 0, j + 5, k + 20, Blocks.planks, 2, 0);
    world.setBlock(i + 0, j + 5, k + 21, Blocks.planks, 2, 0);
    world.setBlock(i + 0, j + 5, k + 22, Blocks.cobblestone);
    world.setBlock(i + 0, j + 5, k + 23, Blocks.planks, 2, 0);
    world.setBlock(i + 0, j + 5, k + 24, Blocks.planks, 2, 0);
    world.setBlock(i + 0, j + 5, k + 25, Blocks.cobblestone);
    world.setBlock(i + 0, j + 6, k + 13, Blocks.cobblestone);
    world.setBlock(i + 0, j + 6, k + 14, Blocks.planks, 2, 0);
    world.setBlock(i + 0, j + 6, k + 15, Blocks.planks, 2, 0);
    world.setBlock(i + 0, j + 6, k + 16, Blocks.cobblestone);
    world.setBlock(i + 0, j + 6, k + 17, Blocks.planks, 2, 0);
    world.setBlock(i + 0, j + 6, k + 18, Blocks.planks, 2, 0);
    world.setBlock(i + 0, j + 6, k + 19, Blocks.cobblestone);
    world.setBlock(i + 0, j + 6, k + 20, Blocks.planks, 2, 0);
    world.setBlock(i + 0, j + 6, k + 21, Blocks.planks, 2, 0);
    world.setBlock(i + 0, j + 6, k + 22, Blocks.cobblestone);
    world.setBlock(i + 0, j + 6, k + 23, Blocks.planks, 2, 0);
    world.setBlock(i + 0, j + 6, k + 24, Blocks.planks, 2, 0);
    world.setBlock(i + 0, j + 6, k + 25, Blocks.cobblestone);
    world.setBlock(i + 0, j + 7, k + 13, Blocks.cobblestone);
    world.setBlock(i + 0, j + 7, k + 14, Blocks.cobblestone);
    world.setBlock(i + 0, j + 7, k + 15, Blocks.planks, 2, 0);
    world.setBlock(i + 0, j + 7, k + 16, Blocks.cobblestone);
    world.setBlock(i + 0, j + 7, k + 17, Blocks.cobblestone);
    world.setBlock(i + 0, j + 7, k + 18, Blocks.cobblestone);
    world.setBlock(i + 0, j + 7, k + 19, Blocks.cobblestone);
    world.setBlock(i + 0, j + 7, k + 20, Blocks.cobblestone);
    world.setBlock(i + 0, j + 7, k + 21, Blocks.cobblestone);
    world.setBlock(i + 0, j + 7, k + 22, Blocks.cobblestone);
    world.setBlock(i + 0, j + 7, k + 23, Blocks.cobblestone);
    world.setBlock(i + 0, j + 7, k + 24, Blocks.cobblestone);
    world.setBlock(i + 0, j + 7, k + 25, Blocks.cobblestone);
    world.setBlock(i + 0, j + 7, k + 26, Blocks.stone_stairs, 7, 0);
    world.setBlock(i + 0, j + 8, k + 13, Blocks.cobblestone);
    world.setBlock(i + 0, j + 8, k + 14, Blocks.cobblestone);
    world.setBlock(i + 0, j + 8, k + 15, Blocks.cobblestone);
    world.setBlock(i + 0, j + 8, k + 16, Blocks.cobblestone);
    world.setBlock(i + 0, j + 8, k + 17, Blocks.cobblestone);
    world.setBlock(i + 0, j + 8, k + 18, Blocks.cobblestone);
    world.setBlock(i + 0, j + 8, k + 19, Blocks.cobblestone);
    world.setBlock(i + 0, j + 8, k + 20, Blocks.cobblestone);
    world.setBlock(i + 0, j + 8, k + 21, Blocks.cobblestone);
    world.setBlock(i + 0, j + 8, k + 22, Blocks.cobblestone);
    world.setBlock(i + 0, j + 8, k + 23, Blocks.cobblestone);
    world.setBlock(i + 0, j + 8, k + 24, Blocks.cobblestone);
    world.setBlock(i + 0, j + 8, k + 25, Blocks.cobblestone);
    world.setBlock(i + 0, j + 8, k + 26, Blocks.cobblestone);
    world.setBlock(i + 0, j + 9, k + 13, Blocks.cobblestone);
    world.setBlock(i + 0, j + 9, k + 14, Blocks.planks, 2, 0);
    world.setBlock(i + 0, j + 9, k + 15, Blocks.planks, 2, 0);
    world.setBlock(i + 0, j + 9, k + 16, Blocks.cobblestone);
    world.setBlock(i + 0, j + 9, k + 17, Blocks.planks, 2, 0);
    world.setBlock(i + 0, j + 9, k + 18, Blocks.planks, 2, 0);
    world.setBlock(i + 0, j + 9, k + 19, Blocks.cobblestone);
    world.setBlock(i + 0, j + 9, k + 20, Blocks.planks, 2, 0);
    world.setBlock(i + 0, j + 9, k + 21, Blocks.planks, 2, 0);
    world.setBlock(i + 0, j + 9, k + 22, Blocks.cobblestone);
    world.setBlock(i + 0, j + 9, k + 23, Blocks.planks, 2, 0);
    world.setBlock(i + 0, j + 9, k + 24, Blocks.planks, 2, 0);
    world.setBlock(i + 0, j + 9, k + 25, Blocks.planks, 2, 0);
    world.setBlock(i + 0, j + 9, k + 26, Blocks.cobblestone);
    world.setBlock(i + 0, j + 10, k + 13, Blocks.cobblestone);
    world.setBlock(i + 0, j + 10, k + 14, Blocks.planks, 2, 0);
    world.setBlock(i + 0, j + 10, k + 15, Blocks.planks, 2, 0);
    world.setBlock(i + 0, j + 10, k + 16, Blocks.cobblestone);
    world.setBlock(i + 0, j + 10, k + 17, Blocks.planks, 2, 0);
    world.setBlock(i + 0, j + 10, k + 18, Blocks.planks, 2, 0);
    world.setBlock(i + 0, j + 10, k + 19, Blocks.cobblestone);
    world.setBlock(i + 0, j + 10, k + 20, Blocks.planks, 2, 0);
    world.setBlock(i + 0, j + 10, k + 21, Blocks.planks, 2, 0);
    world.setBlock(i + 0, j + 10, k + 22, Blocks.cobblestone);
    world.setBlock(i + 0, j + 10, k + 23, Blocks.planks, 2, 0);
    world.setBlock(i + 0, j + 10, k + 24, Blocks.planks, 2, 0);
    world.setBlock(i + 0, j + 10, k + 25, Blocks.planks, 2, 0);
    world.setBlock(i + 0, j + 10, k + 26, Blocks.cobblestone);
    world.setBlock(i + 0, j + 11, k + 13, Blocks.cobblestone);
    world.setBlock(i + 0, j + 11, k + 14, Blocks.planks, 2, 0);
    world.setBlock(i + 0, j + 11, k + 15, Blocks.planks, 2, 0);
    world.setBlock(i + 0, j + 11, k + 16, Blocks.cobblestone);
    world.setBlock(i + 0, j + 11, k + 17, Blocks.planks, 2, 0);
    world.setBlock(i + 0, j + 11, k + 18, Blocks.planks, 2, 0);
    world.setBlock(i + 0, j + 11, k + 19, Blocks.cobblestone);
    world.setBlock(i + 0, j + 11, k + 20, Blocks.planks, 2, 0);
    world.setBlock(i + 0, j + 11, k + 21, Blocks.planks, 2, 0);
    world.setBlock(i + 0, j + 11, k + 22, Blocks.cobblestone);
    world.setBlock(i + 0, j + 11, k + 23, Blocks.planks, 2, 0);
    world.setBlock(i + 0, j + 11, k + 24, Blocks.planks, 2, 0);
    world.setBlock(i + 0, j + 11, k + 25, Blocks.planks, 2, 0);
    world.setBlock(i + 0, j + 11, k + 26, Blocks.cobblestone);
    world.setBlock(i + 0, j + 12, k + 13, Blocks.cobblestone);
    world.setBlock(i + 0, j + 12, k + 14, Blocks.planks, 2, 0);
    world.setBlock(i + 0, j + 12, k + 15, Blocks.planks, 2, 0);
    world.setBlock(i + 0, j + 12, k + 16, Blocks.cobblestone);
    world.setBlock(i + 0, j + 12, k + 17, Blocks.planks, 2, 0);
    world.setBlock(i + 0, j + 12, k + 18, Blocks.planks, 2, 0);
    world.setBlock(i + 0, j + 12, k + 19, Blocks.cobblestone);
    world.setBlock(i + 0, j + 12, k + 20, Blocks.planks, 2, 0);
    world.setBlock(i + 0, j + 12, k + 21, Blocks.planks, 2, 0);
    world.setBlock(i + 0, j + 12, k + 22, Blocks.cobblestone);
    world.setBlock(i + 0, j + 12, k + 23, Blocks.planks, 2, 0);
    world.setBlock(i + 0, j + 12, k + 24, Blocks.planks, 2, 0);
    world.setBlock(i + 0, j + 12, k + 25, Blocks.planks, 2, 0);
    world.setBlock(i + 0, j + 12, k + 26, Blocks.cobblestone);
    world.setBlock(i + 0, j + 13, k + 13, Blocks.cobblestone);
    world.setBlock(i + 0, j + 13, k + 14, Blocks.planks, 2, 0);
    world.setBlock(i + 0, j + 13, k + 15, Blocks.planks, 2, 0);
    world.setBlock(i + 0, j + 13, k + 16, Blocks.cobblestone);
    world.setBlock(i + 0, j + 13, k + 17, Blocks.planks, 2, 0);
    world.setBlock(i + 0, j + 13, k + 18, Blocks.planks, 2, 0);
    world.setBlock(i + 0, j + 13, k + 19, Blocks.cobblestone);
    world.setBlock(i + 0, j + 13, k + 20, Blocks.planks, 2, 0);
    world.setBlock(i + 0, j + 13, k + 21, Blocks.planks, 2, 0);
    world.setBlock(i + 0, j + 13, k + 22, Blocks.cobblestone);
    world.setBlock(i + 0, j + 13, k + 23, Blocks.planks, 2, 0);
    world.setBlock(i + 0, j + 13, k + 24, Blocks.planks, 2, 0);
    world.setBlock(i + 0, j + 13, k + 25, Blocks.planks, 2, 0);
    world.setBlock(i + 0, j + 13, k + 26, Blocks.cobblestone);
    world.setBlock(i + 0, j + 14, k + 13, Blocks.cobblestone);
    world.setBlock(i + 0, j + 14, k + 14, Blocks.planks, 2, 0);
    world.setBlock(i + 0, j + 14, k + 15, Blocks.planks, 2, 0);
    world.setBlock(i + 0, j + 14, k + 16, Blocks.cobblestone);
    world.setBlock(i + 0, j + 14, k + 17, Blocks.planks, 2, 0);
    world.setBlock(i + 0, j + 14, k + 18, Blocks.planks, 2, 0);
    world.setBlock(i + 0, j + 14, k + 19, Blocks.cobblestone);
    world.setBlock(i + 0, j + 14, k + 20, Blocks.planks, 2, 0);
    world.setBlock(i + 0, j + 14, k + 21, Blocks.planks, 2, 0);
    world.setBlock(i + 0, j + 14, k + 22, Blocks.cobblestone);
    world.setBlock(i + 0, j + 14, k + 23, Blocks.planks, 2, 0);
    world.setBlock(i + 0, j + 14, k + 24, Blocks.planks, 2, 0);
    world.setBlock(i + 0, j + 14, k + 25, Blocks.planks, 2, 0);
    world.setBlock(i + 0, j + 14, k + 26, Blocks.cobblestone);
    world.setBlock(i + 0, j + 15, k + 13, Blocks.cobblestone);
    world.setBlock(i + 0, j + 15, k + 14, Blocks.cobblestone);
    world.setBlock(i + 0, j + 15, k + 15, Blocks.cobblestone);
    world.setBlock(i + 0, j + 15, k + 16, Blocks.cobblestone);
    world.setBlock(i + 0, j + 15, k + 17, Blocks.cobblestone);
    world.setBlock(i + 0, j + 15, k + 18, Blocks.cobblestone);
    world.setBlock(i + 0, j + 15, k + 19, Blocks.cobblestone);
    world.setBlock(i + 0, j + 15, k + 20, Blocks.cobblestone);
    world.setBlock(i + 0, j + 15, k + 21, Blocks.cobblestone);
    world.setBlock(i + 0, j + 15, k + 22, Blocks.cobblestone);
    world.setBlock(i + 0, j + 15, k + 23, Blocks.cobblestone);
    world.setBlock(i + 0, j + 15, k + 24, Blocks.cobblestone);
    world.setBlock(i + 0, j + 15, k + 25, Blocks.cobblestone);
    world.setBlock(i + 0, j + 15, k + 26, Blocks.cobblestone);
    world.setBlock(i + 0, j + 15, k + 27, Blocks.stone_stairs, 7, 0);
    world.setBlock(i + 0, j + 16, k + 13, Blocks.cobblestone);
    world.setBlock(i + 0, j + 16, k + 14, Blocks.cobblestone);
    world.setBlock(i + 0, j + 16, k + 15, Blocks.cobblestone);
    world.setBlock(i + 0, j + 16, k + 16, Blocks.cobblestone);
    world.setBlock(i + 0, j + 16, k + 17, Blocks.cobblestone);
    world.setBlock(i + 0, j + 16, k + 18, Blocks.cobblestone);
    world.setBlock(i + 0, j + 16, k + 19, Blocks.cobblestone);
    world.setBlock(i + 0, j + 16, k + 20, Blocks.cobblestone);
    world.setBlock(i + 0, j + 16, k + 21, Blocks.cobblestone);
    world.setBlock(i + 0, j + 16, k + 22, Blocks.cobblestone);
    world.setBlock(i + 0, j + 16, k + 23, Blocks.cobblestone);
    world.setBlock(i + 0, j + 16, k + 24, Blocks.cobblestone);
    world.setBlock(i + 0, j + 16, k + 25, Blocks.cobblestone);
    world.setBlock(i + 0, j + 16, k + 26, Blocks.cobblestone);
    world.setBlock(i + 0, j + 16, k + 27, Blocks.cobblestone);
    world.setBlock(i + 0, j + 17, k + 13, Blocks.cobblestone);
    world.setBlock(i + 0, j + 17, k + 14, Blocks.planks, 2, 0);
    world.setBlock(i + 0, j + 17, k + 15, Blocks.planks, 2, 0);
    world.setBlock(i + 0, j + 17, k + 16, Blocks.cobblestone);
    world.setBlock(i + 0, j + 17, k + 17, Blocks.planks, 2, 0);
    world.setBlock(i + 0, j + 17, k + 18, Blocks.planks, 2, 0);
    world.setBlock(i + 0, j + 17, k + 19, Blocks.cobblestone);
    world.setBlock(i + 0, j + 17, k + 20, Blocks.planks, 2, 0);
    world.setBlock(i + 0, j + 17, k + 21, Blocks.planks, 2, 0);
    world.setBlock(i + 0, j + 17, k + 22, Blocks.cobblestone);
    world.setBlock(i + 0, j + 17, k + 23, Blocks.planks, 2, 0);
    world.setBlock(i + 0, j + 17, k + 24, Blocks.planks, 2, 0);
    world.setBlock(i + 0, j + 17, k + 25, Blocks.cobblestone);
    world.setBlock(i + 0, j + 17, k + 26, Blocks.planks, 2, 0);
    world.setBlock(i + 0, j + 17, k + 27, Blocks.cobblestone);
    world.setBlock(i + 0, j + 18, k + 13, Blocks.cobblestone);
    world.setBlock(i + 0, j + 18, k + 14, Blocks.planks, 2, 0);
    world.setBlock(i + 0, j + 18, k + 15, Blocks.planks, 2, 0);
    world.setBlock(i + 0, j + 18, k + 16, Blocks.cobblestone);
    world.setBlock(i + 0, j + 18, k + 17, Blocks.planks, 2, 0);
    world.setBlock(i + 0, j + 18, k + 18, Blocks.planks, 2, 0);
    world.setBlock(i + 0, j + 18, k + 19, Blocks.cobblestone);
    world.setBlock(i + 0, j + 18, k + 20, Blocks.planks, 2, 0);
    world.setBlock(i + 0, j + 18, k + 21, Blocks.planks, 2, 0);
    world.setBlock(i + 0, j + 18, k + 22, Blocks.cobblestone);
    world.setBlock(i + 0, j + 18, k + 23, Blocks.planks, 2, 0);
    world.setBlock(i + 0, j + 18, k + 24, Blocks.planks, 2, 0);
    world.setBlock(i + 0, j + 18, k + 25, Blocks.cobblestone);
    world.setBlock(i + 0, j + 18, k + 26, Blocks.planks, 2, 0);
    world.setBlock(i + 0, j + 18, k + 27, Blocks.cobblestone);
    world.setBlock(i + 0, j + 19, k + 13, Blocks.cobblestone);
    world.setBlock(i + 0, j + 19, k + 14, Blocks.planks, 2, 0);
    world.setBlock(i + 0, j + 19, k + 15, Blocks.planks, 2, 0);
    world.setBlock(i + 0, j + 19, k + 16, Blocks.cobblestone);
    world.setBlock(i + 0, j + 19, k + 17, Blocks.planks, 2, 0);
    world.setBlock(i + 0, j + 19, k + 18, Blocks.planks, 2, 0);
    world.setBlock(i + 0, j + 19, k + 19, Blocks.cobblestone);
    world.setBlock(i + 0, j + 19, k + 20, Blocks.planks, 2, 0);
    world.setBlock(i + 0, j + 19, k + 21, Blocks.planks, 2, 0);
    world.setBlock(i + 0, j + 19, k + 22, Blocks.cobblestone);
    world.setBlock(i + 0, j + 19, k + 23, Blocks.planks, 2, 0);
    world.setBlock(i + 0, j + 19, k + 24, Blocks.planks, 2, 0);
    world.setBlock(i + 0, j + 19, k + 25, Blocks.cobblestone);
    world.setBlock(i + 0, j + 19, k + 26, Blocks.planks, 2, 0);
    world.setBlock(i + 0, j + 19, k + 27, Blocks.cobblestone);
    world.setBlock(i + 0, j + 20, k + 13, Blocks.cobblestone);
    world.setBlock(i + 0, j + 20, k + 14, Blocks.planks, 2, 0);
    world.setBlock(i + 0, j + 20, k + 15, Blocks.planks, 2, 0);
    world.setBlock(i + 0, j + 20, k + 16, Blocks.cobblestone);
    world.setBlock(i + 0, j + 20, k + 17, Blocks.planks, 2, 0);
    world.setBlock(i + 0, j + 20, k + 18, Blocks.planks, 2, 0);
    world.setBlock(i + 0, j + 20, k + 19, Blocks.cobblestone);
    world.setBlock(i + 0, j + 20, k + 20, Blocks.planks, 2, 0);
    world.setBlock(i + 0, j + 20, k + 21, Blocks.planks, 2, 0);
    world.setBlock(i + 0, j + 20, k + 22, Blocks.cobblestone);
    world.setBlock(i + 0, j + 20, k + 23, Blocks.planks, 2, 0);
    world.setBlock(i + 0, j + 20, k + 24, Blocks.planks, 2, 0);
    world.setBlock(i + 0, j + 20, k + 25, Blocks.cobblestone);
    world.setBlock(i + 0, j + 20, k + 26, Blocks.planks, 2, 0);
    world.setBlock(i + 0, j + 20, k + 27, Blocks.cobblestone);
    world.setBlock(i + 0, j + 21, k + 13, Blocks.cobblestone);
    world.setBlock(i + 0, j + 21, k + 14, Blocks.planks, 2, 0);
    world.setBlock(i + 0, j + 21, k + 15, Blocks.planks, 2, 0);
    world.setBlock(i + 0, j + 21, k + 16, Blocks.cobblestone);
    world.setBlock(i + 0, j + 21, k + 17, Blocks.planks, 2, 0);
    world.setBlock(i + 0, j + 21, k + 18, Blocks.planks, 2, 0);
    world.setBlock(i + 0, j + 21, k + 19, Blocks.cobblestone);
    world.setBlock(i + 0, j + 21, k + 20, Blocks.planks, 2, 0);
    world.setBlock(i + 0, j + 21, k + 21, Blocks.planks, 2, 0);
    world.setBlock(i + 0, j + 21, k + 22, Blocks.cobblestone);
    world.setBlock(i + 0, j + 21, k + 23, Blocks.planks, 2, 0);
    world.setBlock(i + 0, j + 21, k + 24, Blocks.planks, 2, 0);
    world.setBlock(i + 0, j + 21, k + 25, Blocks.cobblestone);
    world.setBlock(i + 0, j + 21, k + 26, Blocks.planks, 2, 0);
    world.setBlock(i + 0, j + 21, k + 27, Blocks.cobblestone);
    world.setBlock(i + 0, j + 22, k + 13, Blocks.cobblestone);
    world.setBlock(i + 0, j + 22, k + 14, Blocks.planks, 2, 0);
    world.setBlock(i + 0, j + 22, k + 15, Blocks.planks, 2, 0);
    world.setBlock(i + 0, j + 22, k + 16, Blocks.cobblestone);
    world.setBlock(i + 0, j + 22, k + 17, Blocks.planks, 2, 0);
    world.setBlock(i + 0, j + 22, k + 18, Blocks.planks, 2, 0);
    world.setBlock(i + 0, j + 22, k + 19, Blocks.cobblestone);
    world.setBlock(i + 0, j + 22, k + 20, Blocks.planks, 2, 0);
    world.setBlock(i + 0, j + 22, k + 21, Blocks.planks, 2, 0);
    world.setBlock(i + 0, j + 22, k + 22, Blocks.cobblestone);
    world.setBlock(i + 0, j + 22, k + 23, Blocks.planks, 2, 0);
    world.setBlock(i + 0, j + 22, k + 24, Blocks.planks, 2, 0);
    world.setBlock(i + 0, j + 22, k + 25, Blocks.cobblestone);
    world.setBlock(i + 0, j + 22, k + 26, Blocks.planks, 2, 0);
    world.setBlock(i + 0, j + 22, k + 27, Blocks.cobblestone);
    world.setBlock(i + 0, j + 23, k + 13, Blocks.cobblestone);
    world.setBlock(i + 0, j + 23, k + 14, Blocks.cobblestone);
    world.setBlock(i + 0, j + 23, k + 15, Blocks.cobblestone);
    world.setBlock(i + 0, j + 23, k + 16, Blocks.cobblestone);
    world.setBlock(i + 0, j + 23, k + 17, Blocks.cobblestone);
    world.setBlock(i + 0, j + 23, k + 18, Blocks.cobblestone);
    world.setBlock(i + 0, j + 23, k + 19, Blocks.cobblestone);
    world.setBlock(i + 0, j + 23, k + 20, Blocks.cobblestone);
    world.setBlock(i + 0, j + 23, k + 21, Blocks.cobblestone);
    world.setBlock(i + 0, j + 23, k + 22, Blocks.cobblestone);
    world.setBlock(i + 0, j + 23, k + 23, Blocks.cobblestone);
    world.setBlock(i + 0, j + 23, k + 24, Blocks.cobblestone);
    world.setBlock(i + 0, j + 23, k + 25, Blocks.cobblestone);
    world.setBlock(i + 0, j + 23, k + 26, Blocks.cobblestone);
    world.setBlock(i + 0, j + 23, k + 27, Blocks.cobblestone);
    world.setBlock(i + 0, j + 23, k + 28, Blocks.stone_stairs, 7, 0);
    world.setBlock(i + 0, j + 24, k + 13, Blocks.cobblestone);
    world.setBlock(i + 0, j + 24, k + 14, Blocks.cobblestone);
    world.setBlock(i + 0, j + 24, k + 15, Blocks.cobblestone);
    world.setBlock(i + 0, j + 24, k + 16, Blocks.cobblestone);
    world.setBlock(i + 0, j + 24, k + 17, Blocks.cobblestone);
    world.setBlock(i + 0, j + 24, k + 18, Blocks.cobblestone);
    world.setBlock(i + 0, j + 24, k + 19, Blocks.cobblestone);
    world.setBlock(i + 0, j + 24, k + 20, Blocks.cobblestone);
    world.setBlock(i + 0, j + 24, k + 21, Blocks.cobblestone);
    world.setBlock(i + 0, j + 24, k + 22, Blocks.cobblestone);
    world.setBlock(i + 0, j + 24, k + 23, Blocks.cobblestone);
    world.setBlock(i + 0, j + 24, k + 24, Blocks.cobblestone);
    world.setBlock(i + 0, j + 24, k + 25, Blocks.cobblestone);
    world.setBlock(i + 0, j + 24, k + 26, Blocks.cobblestone);
    world.setBlock(i + 0, j + 24, k + 27, Blocks.cobblestone);
    world.setBlock(i + 0, j + 24, k + 28, Blocks.cobblestone);
    world.setBlock(i + 0, j + 25, k + 13, Blocks.cobblestone);
    world.setBlock(i + 0, j + 25, k + 14, Blocks.planks, 2, 0);
    world.setBlock(i + 0, j + 25, k + 15, Blocks.planks, 2, 0);
    world.setBlock(i + 0, j + 25, k + 16, Blocks.cobblestone);
    world.setBlock(i + 0, j + 25, k + 17, Blocks.planks, 2, 0);
    world.setBlock(i + 0, j + 25, k + 18, Blocks.planks, 2, 0);
    world.setBlock(i + 0, j + 25, k + 19, Blocks.cobblestone);
    world.setBlock(i + 0, j + 25, k + 20, Blocks.planks, 2, 0);
    world.setBlock(i + 0, j + 25, k + 21, Blocks.planks, 2, 0);
    world.setBlock(i + 0, j + 25, k + 22, Blocks.cobblestone);
    world.setBlock(i + 0, j + 25, k + 23, Blocks.planks, 2, 0);
    world.setBlock(i + 0, j + 25, k + 24, Blocks.planks, 2, 0);
    world.setBlock(i + 0, j + 25, k + 25, Blocks.cobblestone);
    world.setBlock(i + 0, j + 25, k + 26, Blocks.planks, 2, 0);
    world.setBlock(i + 0, j + 25, k + 27, Blocks.planks, 2, 0);
    world.setBlock(i + 0, j + 25, k + 28, Blocks.cobblestone);
    world.setBlock(i + 0, j + 26, k + 13, Blocks.cobblestone);
    world.setBlock(i + 0, j + 26, k + 14, Blocks.planks, 2, 0);
    world.setBlock(i + 0, j + 26, k + 15, Blocks.planks, 2, 0);
    world.setBlock(i + 0, j + 26, k + 16, Blocks.cobblestone);
    world.setBlock(i + 0, j + 26, k + 17, Blocks.planks, 2, 0);
    world.setBlock(i + 0, j + 26, k + 18, Blocks.planks, 2, 0);
    world.setBlock(i + 0, j + 26, k + 19, Blocks.cobblestone);
    world.setBlock(i + 0, j + 26, k + 20, Blocks.planks, 2, 0);
    world.setBlock(i + 0, j + 26, k + 21, Blocks.planks, 2, 0);
    world.setBlock(i + 0, j + 26, k + 22, Blocks.cobblestone);
    world.setBlock(i + 0, j + 26, k + 23, Blocks.planks, 2, 0);
    world.setBlock(i + 0, j + 26, k + 24, Blocks.planks, 2, 0);
    world.setBlock(i + 0, j + 26, k + 25, Blocks.cobblestone);
    world.setBlock(i + 0, j + 26, k + 26, Blocks.planks, 2, 0);
    world.setBlock(i + 0, j + 26, k + 27, Blocks.planks, 2, 0);
    world.setBlock(i + 0, j + 26, k + 28, Blocks.cobblestone);
    world.setBlock(i + 0, j + 27, k + 13, Blocks.stone_stairs);
    world.setBlock(i + 0, j + 27, k + 14, Blocks.cobblestone);
    world.setBlock(i + 0, j + 27, k + 15, Blocks.planks, 2, 0);
    world.setBlock(i + 0, j + 27, k + 16, Blocks.cobblestone);
    world.setBlock(i + 0, j + 27, k + 17, Blocks.planks, 2, 0);
    world.setBlock(i + 0, j + 27, k + 18, Blocks.planks, 2, 0);
    world.setBlock(i + 0, j + 27, k + 19, Blocks.cobblestone);
    world.setBlock(i + 0, j + 27, k + 20, Blocks.planks, 2, 0);
    world.setBlock(i + 0, j + 27, k + 21, Blocks.planks, 2, 0);
    world.setBlock(i + 0, j + 27, k + 22, Blocks.cobblestone);
    world.setBlock(i + 0, j + 27, k + 23, Blocks.planks, 2, 0);
    world.setBlock(i + 0, j + 27, k + 24, Blocks.planks, 2, 0);
    world.setBlock(i + 0, j + 27, k + 25, Blocks.cobblestone);
    world.setBlock(i + 0, j + 27, k + 26, Blocks.planks, 2, 0);
    world.setBlock(i + 0, j + 27, k + 27, Blocks.cobblestone);
    world.setBlock(i + 0, j + 27, k + 28, Blocks.stone_stairs);
    world.setBlock(i + 0, j + 28, k + 14, Blocks.cobblestone);
    world.setBlock(i + 0, j + 28, k + 15, Blocks.planks, 2, 0);
    world.setBlock(i + 0, j + 28, k + 16, Blocks.cobblestone);
    world.setBlock(i + 0, j + 28, k + 17, Blocks.planks, 2, 0);
    world.setBlock(i + 0, j + 28, k + 18, Blocks.planks, 2, 0);
    world.setBlock(i + 0, j + 28, k + 19, Blocks.cobblestone);
    world.setBlock(i + 0, j + 28, k + 20, Blocks.planks, 2, 0);
    world.setBlock(i + 0, j + 28, k + 21, Blocks.planks, 2, 0);
    world.setBlock(i + 0, j + 28, k + 22, Blocks.cobblestone);
    world.setBlock(i + 0, j + 28, k + 23, Blocks.planks, 2, 0);
    world.setBlock(i + 0, j + 28, k + 24, Blocks.planks, 2, 0);
    world.setBlock(i + 0, j + 28, k + 25, Blocks.cobblestone);
    world.setBlock(i + 0, j + 28, k + 26, Blocks.planks, 2, 0);
    world.setBlock(i + 0, j + 28, k + 27, Blocks.cobblestone);
    world.setBlock(i + 0, j + 29, k + 14, Blocks.stone_stairs);
    world.setBlock(i + 0, j + 29, k + 15, Blocks.cobblestone);
    world.setBlock(i + 0, j + 29, k + 16, Blocks.cobblestone);
    world.setBlock(i + 0, j + 29, k + 17, Blocks.planks, 2, 0);
    world.setBlock(i + 0, j + 29, k + 18, Blocks.planks, 2, 0);
    world.setBlock(i + 0, j + 29, k + 19, Blocks.cobblestone);
    world.setBlock(i + 0, j + 29, k + 20, Blocks.planks, 2, 0);
    world.setBlock(i + 0, j + 29, k + 21, Blocks.planks, 2, 0);
    world.setBlock(i + 0, j + 29, k + 22, Blocks.cobblestone);
    world.setBlock(i + 0, j + 29, k + 23, Blocks.planks, 2, 0);
    world.setBlock(i + 0, j + 29, k + 24, Blocks.planks, 2, 0);
    world.setBlock(i + 0, j + 29, k + 25, Blocks.cobblestone);
    world.setBlock(i + 0, j + 29, k + 26, Blocks.cobblestone);
    world.setBlock(i + 0, j + 29, k + 27, Blocks.stone_stairs);
    world.setBlock(i + 0, j + 30, k + 15, Blocks.cobblestone);
    world.setBlock(i + 0, j + 30, k + 16, Blocks.cobblestone);
    world.setBlock(i + 0, j + 30, k + 17, Blocks.planks, 2, 0);
    world.setBlock(i + 0, j + 30, k + 18, Blocks.planks, 2, 0);
    world.setBlock(i + 0, j + 30, k + 19, Blocks.cobblestone);
    world.setBlock(i + 0, j + 30, k + 20, Blocks.planks, 2, 0);
    world.setBlock(i + 0, j + 30, k + 21, Blocks.planks, 2, 0);
    world.setBlock(i + 0, j + 30, k + 22, Blocks.cobblestone);
    world.setBlock(i + 0, j + 30, k + 23, Blocks.planks, 2, 0);
    world.setBlock(i + 0, j + 30, k + 24, Blocks.planks, 2, 0);
    world.setBlock(i + 0, j + 30, k + 25, Blocks.cobblestone);
    world.setBlock(i + 0, j + 30, k + 26, Blocks.cobblestone);
    world.setBlock(i + 0, j + 31, k + 15, Blocks.stone_stairs);
    world.setBlock(i + 0, j + 31, k + 16, Blocks.cobblestone);
    world.setBlock(i + 0, j + 31, k + 17, Blocks.cobblestone);
    world.setBlock(i + 0, j + 31, k + 18, Blocks.cobblestone);
    world.setBlock(i + 0, j + 31, k + 19, Blocks.cobblestone);
    world.setBlock(i + 0, j + 31, k + 20, Blocks.cobblestone);
    world.setBlock(i + 0, j + 31, k + 21, Blocks.cobblestone);
    world.setBlock(i + 0, j + 31, k + 22, Blocks.cobblestone);
    world.setBlock(i + 0, j + 31, k + 23, Blocks.cobblestone);
    world.setBlock(i + 0, j + 31, k + 24, Blocks.cobblestone);
    world.setBlock(i + 0, j + 31, k + 25, Blocks.cobblestone);
    world.setBlock(i + 0, j + 31, k + 26, Blocks.stone_stairs);
    world.setBlock(i + 0, j + 32, k + 16, Blocks.cobblestone);
    world.setBlock(i + 0, j + 32, k + 17, Blocks.cobblestone);
    world.setBlock(i + 0, j + 32, k + 18, Blocks.cobblestone);
    world.setBlock(i + 0, j + 32, k + 19, Blocks.cobblestone);
    world.setBlock(i + 0, j + 32, k + 20, Blocks.cobblestone);
    world.setBlock(i + 0, j + 32, k + 21, Blocks.cobblestone);
    world.setBlock(i + 0, j + 32, k + 22, Blocks.cobblestone);
    world.setBlock(i + 0, j + 32, k + 23, Blocks.cobblestone);
    world.setBlock(i + 0, j + 32, k + 24, Blocks.cobblestone);
    world.setBlock(i + 0, j + 32, k + 25, Blocks.cobblestone);
    world.setBlock(i + 0, j + 33, k + 16, Blocks.stone_stairs);
    world.setBlock(i + 0, j + 33, k + 17, Blocks.stone_stairs);
    world.setBlock(i + 0, j + 33, k + 18, Blocks.stone_stairs);
    world.setBlock(i + 0, j + 33, k + 19, Blocks.stone_stairs);
    world.setBlock(i + 0, j + 33, k + 20, Blocks.stone_stairs);
    world.setBlock(i + 0, j + 33, k + 21, Blocks.stone_stairs);
    world.setBlock(i + 0, j + 33, k + 22, Blocks.stone_stairs);
    world.setBlock(i + 0, j + 33, k + 23, Blocks.stone_stairs);
    world.setBlock(i + 0, j + 33, k + 24, Blocks.stone_stairs);
    world.setBlock(i + 0, j + 33, k + 25, Blocks.stone_stairs);
    world.setBlock(i + 1, j + 0, k + 0, Blocks.grass);
    world.setBlock(i + 1, j + 0, k + 5, Blocks.planks, 2, 0);
    world.setBlock(i + 1, j + 0, k + 6, Blocks.farmland, 7, 0);
    world.setBlock(i + 1, j + 0, k + 7, Blocks.farmland, 7, 0);
    world.setBlock(i + 1, j + 0, k + 9, Blocks.farmland, 7, 0);
    world.setBlock(i + 1, j + 0, k + 10, Blocks.farmland, 7, 0);
    world.setBlock(i + 1, j + 0, k + 11, Blocks.planks, 2, 0);
    world.setBlock(i + 1, j + 0, k + 12, Blocks.grass);
    world.setBlock(i + 1, j + 0, k + 13, Blocks.dirt);
    world.setBlock(i + 1, j + 0, k + 14, Blocks.planks, 2, 0);
    world.setBlock(i + 1, j + 0, k + 15, Blocks.planks, 2, 0);
    world.setBlock(i + 1, j + 0, k + 16, Blocks.planks, 2, 0);
    world.setBlock(i + 1, j + 0, k + 17, Blocks.planks, 2, 0);
    world.setBlock(i + 1, j + 0, k + 18, Blocks.planks, 2, 0);
    world.setBlock(i + 1, j + 0, k + 19, Blocks.planks, 2, 0);
    world.setBlock(i + 1, j + 0, k + 20, Blocks.planks, 2, 0);
    world.setBlock(i + 1, j + 0, k + 21, Blocks.planks, 2, 0);
    world.setBlock(i + 1, j + 0, k + 22, Blocks.planks, 2, 0);
    world.setBlock(i + 1, j + 0, k + 23, Blocks.planks, 2, 0);
    world.setBlock(i + 1, j + 0, k + 24, Blocks.planks, 2, 0);
    world.setBlock(i + 1, j + 0, k + 25, Blocks.dirt);
    world.setBlock(i + 1, j + 0, k + 26, Blocks.grass);
    world.setBlock(i + 1, j + 0, k + 27, Blocks.grass);
    world.setBlock(i + 1, j + 0, k + 28, Blocks.stonebrick);
    world.setBlock(i + 1, j + 1, k + 0, Blocks.fence);
    world.setBlock(i + 1, j + 1, k + 6, Blocks.carrots, 7, 0);
    world.setBlock(i + 1, j + 1, k + 7, Blocks.carrots, 7, 0);
    world.setBlock(i + 1, j + 1, k + 9, Blocks.potatoes, 6, 0);
    world.setBlock(i + 1, j + 1, k + 10, Blocks.potatoes, 7, 0);
    world.setBlock(i + 1, j + 1, k + 13, Blocks.planks, 2, 0);
    world.setBlock(i + 1, j + 1, k + 20, Blocks.stone_stairs, 5, 0);
    world.setBlock(i + 1, j + 1, k + 21, Blocks.cobblestone);
    world.setBlock(i + 1, j + 1, k + 22, Blocks.birch_stairs, 3, 0);
    world.setBlock(i + 1, j + 1, k + 25, Blocks.planks, 2, 0);
    world.setBlock(i + 1, j + 1, k + 26, Blocks.leaves, 5, 0);
    world.setBlock(i + 1, j + 2, k + 13, Blocks.glass_pane);
    world.setBlock(i + 1, j + 2, k + 19, Blocks.stone_stairs, 5, 0);
    world.setBlock(i + 1, j + 2, k + 20, Blocks.cobblestone);
    world.setBlock(i + 1, j + 2, k + 21, Blocks.birch_stairs, 3, 0);
    world.setBlock(i + 1, j + 2, k + 25, Blocks.iron_bars);
    world.setBlock(i + 1, j + 3, k + 13, Blocks.glass_pane);
    world.setBlock(i + 1, j + 3, k + 18, Blocks.stone_stairs, 5, 0);
    world.setBlock(i + 1, j + 3, k + 19, Blocks.cobblestone);
    world.setBlock(i + 1, j + 3, k + 20, Blocks.birch_stairs, 3, 0);
    world.setBlock(i + 1, j + 3, k + 25, Blocks.iron_bars);
    world.setBlock(i + 1, j + 4, k + 13, Blocks.planks, 2, 0);
    world.setBlock(i + 1, j + 4, k + 17, Blocks.stone_stairs, 5, 0);
    world.setBlock(i + 1, j + 4, k + 18, Blocks.cobblestone);
    world.setBlock(i + 1, j + 4, k + 19, Blocks.birch_stairs, 3, 0);
    world.setBlock(i + 1, j + 4, k + 25, Blocks.planks, 2, 0);
    world.setBlock(i + 1, j + 5, k + 13, Blocks.glass_pane);
    world.setBlock(i + 1, j + 5, k + 16, Blocks.stone_stairs, 5, 0);
    world.setBlock(i + 1, j + 5, k + 17, Blocks.cobblestone);
    world.setBlock(i + 1, j + 5, k + 18, Blocks.birch_stairs, 3, 0);
    world.setBlock(i + 1, j + 5, k + 25, Blocks.iron_bars);
    world.setBlock(i + 1, j + 6, k + 13, Blocks.glass_pane);
    world.setBlock(i + 1, j + 6, k + 15, Blocks.stone_stairs, 5, 0);
    world.setBlock(i + 1, j + 6, k + 16, Blocks.cobblestone);
    world.setBlock(i + 1, j + 6, k + 17, Blocks.birch_stairs, 3, 0);
    world.setBlock(i + 1, j + 6, k + 25, Blocks.iron_bars);
    world.setBlock(i + 1, j + 7, k + 13, Blocks.stone_stairs, 5, 0);
    world.setBlock(i + 1, j + 7, k + 14, Blocks.stone_stairs, 5, 0);
    world.setBlock(i + 1, j + 7, k + 15, Blocks.cobblestone);
    world.setBlock(i + 1, j + 7, k + 16, Blocks.birch_stairs, 3, 0);
    world.setBlock(i + 1, j + 7, k + 25, Blocks.stone_stairs, 5, 0);
    world.setBlock(i + 1, j + 8, k + 13, Blocks.cobblestone);
    world.setBlock(i + 1, j + 8, k + 14, Blocks.cobblestone);
    world.setBlock(i + 1, j + 8, k + 15, Blocks.birch_stairs, 3, 0);
    world.setBlock(i + 1, j + 8, k + 20, Blocks.cobblestone);
    world.setBlock(i + 1, j + 8, k + 21, Blocks.cobblestone);
    world.setBlock(i + 1, j + 8, k + 22, Blocks.cobblestone);
    world.setBlock(i + 1, j + 8, k + 23, Blocks.cobblestone);
    world.setBlock(i + 1, j + 8, k + 24, Blocks.cobblestone);
    world.setBlock(i + 1, j + 8, k + 25, Blocks.cobblestone);
    world.setBlock(i + 1, j + 8, k + 26, Blocks.cobblestone);
    world.setBlock(i + 1, j + 9, k + 13, Blocks.planks, 2, 0);
    world.setBlock(i + 1, j + 9, k + 21, Blocks.stone_stairs, 5, 0);
    world.setBlock(i + 1, j + 9, k + 22, Blocks.cobblestone);
    world.setBlock(i + 1, j + 9, k + 23, Blocks.birch_stairs, 3, 0);
    world.setBlock(i + 1, j + 9, k + 26, Blocks.planks, 2, 0);
    world.setBlock(i + 1, j + 10, k + 13, Blocks.glass_pane);
    world.setBlock(i + 1, j + 10, k + 20, Blocks.stone_stairs, 5, 0);
    world.setBlock(i + 1, j + 10, k + 21, Blocks.cobblestone);
    world.setBlock(i + 1, j + 10, k + 22, Blocks.birch_stairs, 3, 0);
    world.setBlock(i + 1, j + 10, k + 26, Blocks.glass_pane);
    world.setBlock(i + 1, j + 11, k + 13, Blocks.glass_pane);
    world.setBlock(i + 1, j + 11, k + 19, Blocks.stone_stairs, 5, 0);
    world.setBlock(i + 1, j + 11, k + 20, Blocks.cobblestone);
    world.setBlock(i + 1, j + 11, k + 21, Blocks.birch_stairs, 3, 0);
    world.setBlock(i + 1, j + 11, k + 26, Blocks.glass_pane);
    world.setBlock(i + 1, j + 12, k + 13, Blocks.planks, 2, 0);
    world.setBlock(i + 1, j + 12, k + 18, Blocks.stone_stairs, 5, 0);
    world.setBlock(i + 1, j + 12, k + 19, Blocks.cobblestone);
    world.setBlock(i + 1, j + 12, k + 20, Blocks.birch_stairs, 3, 0);
    world.setBlock(i + 1, j + 12, k + 26, Blocks.planks, 2, 0);
    world.setBlock(i + 1, j + 13, k + 13, Blocks.glass_pane);
    world.setBlock(i + 1, j + 13, k + 17, Blocks.stone_stairs, 5, 0);
    world.setBlock(i + 1, j + 13, k + 18, Blocks.cobblestone);
    world.setBlock(i + 1, j + 13, k + 19, Blocks.birch_stairs, 3, 0);
    world.setBlock(i + 1, j + 13, k + 26, Blocks.glass_pane);
    world.setBlock(i + 1, j + 14, k + 13, Blocks.glass_pane);
    world.setBlock(i + 1, j + 14, k + 16, Blocks.stone_stairs, 5, 0);
    world.setBlock(i + 1, j + 14, k + 17, Blocks.cobblestone);
    world.setBlock(i + 1, j + 14, k + 18, Blocks.birch_stairs, 3, 0);
    world.setBlock(i + 1, j + 14, k + 26, Blocks.glass_pane);
    world.setBlock(i + 1, j + 15, k + 13, Blocks.stone_stairs, 5, 0);
    world.setBlock(i + 1, j + 15, k + 15, Blocks.stone_stairs, 5, 0);
    world.setBlock(i + 1, j + 15, k + 16, Blocks.cobblestone);
    world.setBlock(i + 1, j + 15, k + 17, Blocks.birch_stairs, 3, 0);
    world.setBlock(i + 1, j + 15, k + 26, Blocks.stone_stairs, 5, 0);
    world.setBlock(i + 1, j + 16, k + 13, Blocks.cobblestone);
    world.setBlock(i + 1, j + 16, k + 14, Blocks.cobblestone);
    world.setBlock(i + 1, j + 16, k + 15, Blocks.cobblestone);
    world.setBlock(i + 1, j + 16, k + 16, Blocks.birch_stairs, 3, 0);
    world.setBlock(i + 1, j + 16, k + 21, Blocks.cobblestone);
    world.setBlock(i + 1, j + 16, k + 22, Blocks.cobblestone);
    world.setBlock(i + 1, j + 16, k + 23, Blocks.cobblestone);
    world.setBlock(i + 1, j + 16, k + 24, Blocks.cobblestone);
    world.setBlock(i + 1, j + 16, k + 25, Blocks.cobblestone);
    world.setBlock(i + 1, j + 16, k + 26, Blocks.cobblestone);
    world.setBlock(i + 1, j + 16, k + 27, Blocks.cobblestone);
    world.setBlock(i + 1, j + 17, k + 13, Blocks.planks, 2, 0);
    world.setBlock(i + 1, j + 17, k + 22, Blocks.stone_stairs, 5, 0);
    world.setBlock(i + 1, j + 17, k + 23, Blocks.cobblestone);
    world.setBlock(i + 1, j + 17, k + 24, Blocks.birch_stairs, 3, 0);
    world.setBlock(i + 1, j + 17, k + 27, Blocks.planks, 2, 0);
    world.setBlock(i + 1, j + 18, k + 13, Blocks.glass_pane);
    world.setBlock(i + 1, j + 18, k + 21, Blocks.stone_stairs, 5, 0);
    world.setBlock(i + 1, j + 18, k + 22, Blocks.cobblestone);
    world.setBlock(i + 1, j + 18, k + 23, Blocks.birch_stairs, 3, 0);
    world.setBlock(i + 1, j + 18, k + 27, Blocks.glass_pane);
    world.setBlock(i + 1, j + 19, k + 13, Blocks.glass_pane);
    world.setBlock(i + 1, j + 19, k + 20, Blocks.stone_stairs, 5, 0);
    world.setBlock(i + 1, j + 19, k + 21, Blocks.cobblestone);
    world.setBlock(i + 1, j + 19, k + 22, Blocks.birch_stairs, 3, 0);
    world.setBlock(i + 1, j + 19, k + 27, Blocks.glass_pane);
    world.setBlock(i + 1, j + 20, k + 13, Blocks.planks, 2, 0);
    world.setBlock(i + 1, j + 20, k + 19, Blocks.stone_stairs, 5, 0);
    world.setBlock(i + 1, j + 20, k + 20, Blocks.cobblestone);
    world.setBlock(i + 1, j + 20, k + 21, Blocks.birch_stairs, 3, 0);
    world.setBlock(i + 1, j + 20, k + 27, Blocks.planks, 2, 0);
    world.setBlock(i + 1, j + 21, k + 13, Blocks.glass_pane);
    world.setBlock(i + 1, j + 21, k + 18, Blocks.stone_stairs, 5, 0);
    world.setBlock(i + 1, j + 21, k + 19, Blocks.cobblestone);
    world.setBlock(i + 1, j + 21, k + 20, Blocks.birch_stairs, 3, 0);
    world.setBlock(i + 1, j + 21, k + 27, Blocks.glass_pane);
    world.setBlock(i + 1, j + 22, k + 13, Blocks.glass_pane);
    world.setBlock(i + 1, j + 22, k + 17, Blocks.stone_stairs, 5, 0);
    world.setBlock(i + 1, j + 22, k + 18, Blocks.cobblestone);
    world.setBlock(i + 1, j + 22, k + 19, Blocks.birch_stairs, 3, 0);
    world.setBlock(i + 1, j + 22, k + 27, Blocks.glass_pane);
    world.setBlock(i + 1, j + 23, k + 13, Blocks.stone_stairs, 5, 0);
    world.setBlock(i + 1, j + 23, k + 16, Blocks.stone_stairs, 5, 0);
    world.setBlock(i + 1, j + 23, k + 17, Blocks.cobblestone);
    world.setBlock(i + 1, j + 23, k + 18, Blocks.birch_stairs, 3, 0);
    world.setBlock(i + 1, j + 23, k + 27, Blocks.stone_stairs, 5, 0);
    world.setBlock(i + 1, j + 24, k + 13, Blocks.cobblestone);
    world.setBlock(i + 1, j + 24, k + 14, Blocks.cobblestone);
    world.setBlock(i + 1, j + 24, k + 15, Blocks.cobblestone);
    world.setBlock(i + 1, j + 24, k + 16, Blocks.cobblestone);
    world.setBlock(i + 1, j + 24, k + 17, Blocks.birch_stairs, 3, 0);
    world.setBlock(i + 1, j + 24, k + 22, Blocks.cobblestone);
    world.setBlock(i + 1, j + 24, k + 23, Blocks.cobblestone);
    world.setBlock(i + 1, j + 24, k + 24, Blocks.cobblestone);
    world.setBlock(i + 1, j + 24, k + 25, Blocks.cobblestone);
    world.setBlock(i + 1, j + 24, k + 26, Blocks.cobblestone);
    world.setBlock(i + 1, j + 24, k + 27, Blocks.cobblestone);
    world.setBlock(i + 1, j + 24, k + 28, Blocks.cobblestone);
    world.setBlock(i + 1, j + 25, k + 13, Blocks.planks, 3, 0);
    world.setBlock(i + 1, j + 25, k + 22, Blocks.stone_stairs, 5, 0);
    world.setBlock(i + 1, j + 25, k + 23, Blocks.cobblestone);
    world.setBlock(i + 1, j + 25, k + 24, Blocks.birch_stairs, 3, 0);
    world.setBlock(i + 1, j + 25, k + 28, Blocks.planks, 3, 0);
    world.setBlock(i + 1, j + 26, k + 14, Blocks.planks, 3, 0);
    world.setBlock(i + 1, j + 26, k + 21, Blocks.stone_stairs, 5, 0);
    world.setBlock(i + 1, j + 26, k + 22, Blocks.cobblestone);
    world.setBlock(i + 1, j + 26, k + 23, Blocks.birch_stairs, 3, 0);
    world.setBlock(i + 1, j + 26, k + 27, Blocks.planks, 3, 0);
    world.setBlock(i + 1, j + 27, k + 14, Blocks.planks, 3, 0);
    world.setBlock(i + 1, j + 27, k + 19, Blocks.stone_stairs, 5, 0);
    world.setBlock(i + 1, j + 27, k + 20, Blocks.stone_stairs, 5, 0);
    world.setBlock(i + 1, j + 27, k + 21, Blocks.cobblestone);
    world.setBlock(i + 1, j + 27, k + 22, Blocks.birch_stairs, 3, 0);
    world.setBlock(i + 1, j + 27, k + 27, Blocks.planks, 3, 0);
    world.setBlock(i + 1, j + 28, k + 15, Blocks.planks, 3, 0);
    world.setBlock(i + 1, j + 28, k + 19, Blocks.cobblestone);
    world.setBlock(i + 1, j + 28, k + 20, Blocks.cobblestone);
    world.setBlock(i + 1, j + 28, k + 21, Blocks.birch_stairs, 3, 0);
    world.setBlock(i + 1, j + 28, k + 26, Blocks.planks, 3, 0);
    world.setBlock(i + 1, j + 29, k + 15, Blocks.planks, 3, 0);
    world.setBlock(i + 1, j + 29, k + 18, Blocks.fence);
    world.setBlock(i + 1, j + 29, k + 19, Blocks.planks, 2, 0);
    world.setBlock(i + 1, j + 29, k + 20, Blocks.birch_stairs, 3, 0);
    world.setBlock(i + 1, j + 29, k + 26, Blocks.planks, 3, 0);
    world.setBlock(i + 1, j + 30, k + 16, Blocks.planks, 3, 0);
    world.setBlock(i + 1, j + 30, k + 18, Blocks.fence);
    world.setBlock(i + 1, j + 30, k + 25, Blocks.planks, 3, 0);
    world.setBlock(i + 1, j + 31, k + 16, Blocks.planks, 3, 0);
    world.setBlock(i + 1, j + 31, k + 25, Blocks.planks, 3, 0);
    world.setBlock(i + 1, j + 32, k + 17, Blocks.planks, 3, 0);
    world.setBlock(i + 1, j + 32, k + 24, Blocks.planks, 3, 0);
    world.setBlock(i + 1, j + 33, k + 17, Blocks.planks, 3, 0);
    world.setBlock(i + 1, j + 33, k + 24, Blocks.planks, 3, 0);
    world.setBlock(i + 1, j + 34, k + 18, Blocks.planks, 3, 0);
    world.setBlock(i + 1, j + 34, k + 19, Blocks.planks, 3, 0);
    world.setBlock(i + 1, j + 34, k + 20, Blocks.planks, 3, 0);
    world.setBlock(i + 1, j + 34, k + 21, Blocks.planks, 3, 0);
    world.setBlock(i + 1, j + 34, k + 22, Blocks.planks, 3, 0);
    world.setBlock(i + 1, j + 34, k + 23, Blocks.planks, 3, 0);
    world.setBlock(i + 1, j + 35, k + 18, Blocks.planks, 3, 0);
    world.setBlock(i + 1, j + 35, k + 19, Blocks.planks, 3, 0);
    world.setBlock(i + 1, j + 35, k + 20, Blocks.planks, 3, 0);
    world.setBlock(i + 1, j + 35, k + 21, Blocks.planks, 3, 0);
    world.setBlock(i + 1, j + 35, k + 22, Blocks.planks, 3, 0);
    world.setBlock(i + 1, j + 35, k + 23, Blocks.planks, 3, 0);
    world.setBlock(i + 2, j + 0, k + 0, Blocks.grass);
    world.setBlock(i + 2, j + 0, k + 1, Blocks.planks, 2, 0);
    world.setBlock(i + 2, j + 0, k + 2, Blocks.planks, 2, 0);
    world.setBlock(i + 2, j + 0, k + 3, Blocks.planks, 2, 0);
    world.setBlock(i + 2, j + 0, k + 4, Blocks.planks, 2, 0);
    world.setBlock(i + 2, j + 0, k + 5, Blocks.planks, 2, 0);
    world.setBlock(i + 2, j + 0, k + 6, Blocks.farmland, 7, 0);
    world.setBlock(i + 2, j + 0, k + 7, Blocks.farmland, 7, 0);
    world.setBlock(i + 2, j + 0, k + 9, Blocks.farmland, 7, 0);
    world.setBlock(i + 2, j + 0, k + 10, Blocks.farmland, 7, 0);
    world.setBlock(i + 2, j + 0, k + 11, Blocks.planks, 2, 0);
    world.setBlock(i + 2, j + 0, k + 12, Blocks.grass);
    world.setBlock(i + 2, j + 0, k + 13, Blocks.dirt);
    world.setBlock(i + 2, j + 0, k + 14, Blocks.planks, 2, 0);
    world.setBlock(i + 2, j + 0, k + 15, Blocks.planks, 2, 0);
    world.setBlock(i + 2, j + 0, k + 16, Blocks.planks, 2, 0);
    world.setBlock(i + 2, j + 0, k + 17, Blocks.planks, 2, 0);
    world.setBlock(i + 2, j + 0, k + 18, Blocks.planks, 2, 0);
    world.setBlock(i + 2, j + 0, k + 19, Blocks.planks, 2, 0);
    world.setBlock(i + 2, j + 0, k + 20, Blocks.planks, 2, 0);
    world.setBlock(i + 2, j + 0, k + 21, Blocks.planks, 2, 0);
    world.setBlock(i + 2, j + 0, k + 22, Blocks.planks, 2, 0);
    world.setBlock(i + 2, j + 0, k + 23, Blocks.planks, 2, 0);
    world.setBlock(i + 2, j + 0, k + 24, Blocks.planks, 2, 0);
    world.setBlock(i + 2, j + 0, k + 25, Blocks.dirt);
    world.setBlock(i + 2, j + 0, k + 26, Blocks.grass);
    world.setBlock(i + 2, j + 0, k + 27, Blocks.grass);
    world.setBlock(i + 2, j + 0, k + 28, Blocks.stonebrick);
    world.setBlock(i + 2, j + 1, k + 0, Blocks.fence);
    world.setBlock(i + 2, j + 1, k + 6, Blocks.carrots, 7, 0);
    world.setBlock(i + 2, j + 1, k + 7, Blocks.carrots, 7, 0);
    world.setBlock(i + 2, j + 1, k + 9, Blocks.potatoes, 7, 0);
    world.setBlock(i + 2, j + 1, k + 10, Blocks.potatoes, 7, 0);
    world.setBlock(i + 2, j + 1, k + 13, Blocks.planks, 2, 0);
    world.setBlock(i + 2, j + 1, k + 21, Blocks.fence);
    world.setBlock(i + 2, j + 1, k + 22, Blocks.fence);
    world.setBlock(i + 2, j + 1, k + 25, Blocks.planks, 2, 0);
    world.setBlock(i + 2, j + 1, k + 26, Blocks.leaves, 5, 0);
    world.setBlock(i + 2, j + 2, k + 13, Blocks.glass_pane);
    world.setBlock(i + 2, j + 2, k + 20, Blocks.fence);
    world.setBlock(i + 2, j + 2, k + 21, Blocks.fence);
    world.setBlock(i + 2, j + 2, k + 22, Blocks.fence);
    world.setBlock(i + 2, j + 2, k + 25, Blocks.iron_bars);
    world.setBlock(i + 2, j + 3, k + 13, Blocks.glass_pane);
    world.setBlock(i + 2, j + 3, k + 19, Blocks.fence);
    world.setBlock(i + 2, j + 3, k + 20, Blocks.fence);
    world.setBlock(i + 2, j + 3, k + 21, Blocks.fence);
    world.setBlock(i + 2, j + 3, k + 25, Blocks.iron_bars);
    world.setBlock(i + 2, j + 4, k + 13, Blocks.planks, 2, 0);
    world.setBlock(i + 2, j + 4, k + 18, Blocks.fence);
    world.setBlock(i + 2, j + 4, k + 19, Blocks.fence);
    world.setBlock(i + 2, j + 4, k + 20, Blocks.fence);
    world.setBlock(i + 2, j + 4, k + 25, Blocks.planks, 2, 0);
    world.setBlock(i + 2, j + 5, k + 13, Blocks.glass_pane);
    world.setBlock(i + 2, j + 5, k + 17, Blocks.fence);
    world.setBlock(i + 2, j + 5, k + 18, Blocks.fence);
    world.setBlock(i + 2, j + 5, k + 19, Blocks.fence);
    world.setBlock(i + 2, j + 5, k + 25, Blocks.iron_bars);
    world.setBlock(i + 2, j + 6, k + 13, Blocks.glass_pane);
    world.setBlock(i + 2, j + 6, k + 16, Blocks.fence);
    world.setBlock(i + 2, j + 6, k + 17, Blocks.fence);
    world.setBlock(i + 2, j + 6, k + 18, Blocks.fence);
    world.setBlock(i + 2, j + 6, k + 25, Blocks.iron_bars);
    world.setBlock(i + 2, j + 7, k + 13, Blocks.stone_stairs, 4, 0);
    world.setBlock(i + 2, j + 7, k + 15, Blocks.fence);
    world.setBlock(i + 2, j + 7, k + 16, Blocks.fence);
    world.setBlock(i + 2, j + 7, k + 17, Blocks.fence);
    world.setBlock(i + 2, j + 7, k + 25, Blocks.stone_stairs, 4, 0);
    world.setBlock(i + 2, j + 8, k + 13, Blocks.cobblestone);
    world.setBlock(i + 2, j + 8, k + 14, Blocks.cobblestone);
    world.setBlock(i + 2, j + 8, k + 15, Blocks.cobblestone);
    world.setBlock(i + 2, j + 8, k + 16, Blocks.cobblestone);
    world.setBlock(i + 2, j + 8, k + 17, Blocks.cobblestone);
    world.setBlock(i + 2, j + 8, k + 18, Blocks.cobblestone);
    world.setBlock(i + 2, j + 8, k + 19, Blocks.cobblestone);
    world.setBlock(i + 2, j + 8, k + 20, Blocks.cobblestone);
    world.setBlock(i + 2, j + 8, k + 21, Blocks.cobblestone);
    world.setBlock(i + 2, j + 8, k + 22, Blocks.cobblestone);
    world.setBlock(i + 2, j + 8, k + 23, Blocks.cobblestone);
    world.setBlock(i + 2, j + 8, k + 24, Blocks.cobblestone);
    world.setBlock(i + 2, j + 8, k + 25, Blocks.cobblestone);
    world.setBlock(i + 2, j + 8, k + 26, Blocks.cobblestone);
    world.setBlock(i + 2, j + 9, k + 13, Blocks.planks, 2, 0);
    world.setBlock(i + 2, j + 9, k + 15, Blocks.fence);
    world.setBlock(i + 2, j + 9, k + 16, Blocks.fence);
    world.setBlock(i + 2, j + 9, k + 17, Blocks.fence);
    world.setBlock(i + 2, j + 9, k + 18, Blocks.fence);
    world.setBlock(i + 2, j + 9, k + 19, Blocks.fence);
    world.setBlock(i + 2, j + 9, k + 20, Blocks.fence);
    world.setBlock(i + 2, j + 9, k + 21, Blocks.fence);
    world.setBlock(i + 2, j + 9, k + 22, Blocks.fence);
    world.setBlock(i + 2, j + 9, k + 23, Blocks.fence);
    world.setBlock(i + 2, j + 9, k + 26, Blocks.planks, 2, 0);
    world.setBlock(i + 2, j + 10, k + 13, Blocks.glass_pane);
    world.setBlock(i + 2, j + 10, k + 21, Blocks.fence);
    world.setBlock(i + 2, j + 10, k + 22, Blocks.fence);
    world.setBlock(i + 2, j + 10, k + 23, Blocks.fence);
    world.setBlock(i + 2, j + 10, k + 26, Blocks.glass_pane);
    world.setBlock(i + 2, j + 11, k + 13, Blocks.glass_pane);
    world.setBlock(i + 2, j + 11, k + 20, Blocks.fence);
    world.setBlock(i + 2, j + 11, k + 21, Blocks.fence);
    world.setBlock(i + 2, j + 11, k + 22, Blocks.fence);
    world.setBlock(i + 2, j + 11, k + 26, Blocks.glass_pane);
    world.setBlock(i + 2, j + 12, k + 13, Blocks.planks, 2, 0);
    world.setBlock(i + 2, j + 12, k + 19, Blocks.fence);
    world.setBlock(i + 2, j + 12, k + 20, Blocks.fence);
    world.setBlock(i + 2, j + 12, k + 21, Blocks.fence);
    world.setBlock(i + 2, j + 12, k + 26, Blocks.planks, 2, 0);
    world.setBlock(i + 2, j + 13, k + 13, Blocks.glass_pane);
    world.setBlock(i + 2, j + 13, k + 18, Blocks.fence);
    world.setBlock(i + 2, j + 13, k + 19, Blocks.fence);
    world.setBlock(i + 2, j + 13, k + 20, Blocks.fence);
    world.setBlock(i + 2, j + 13, k + 26, Blocks.glass_pane);
    world.setBlock(i + 2, j + 14, k + 13, Blocks.glass_pane);
    world.setBlock(i + 2, j + 14, k + 17, Blocks.fence);
    world.setBlock(i + 2, j + 14, k + 18, Blocks.fence);
    world.setBlock(i + 2, j + 14, k + 19, Blocks.fence);
    world.setBlock(i + 2, j + 14, k + 26, Blocks.glass_pane);
    world.setBlock(i + 2, j + 15, k + 13, Blocks.stone_stairs, 4, 0);
    world.setBlock(i + 2, j + 15, k + 16, Blocks.fence);
    world.setBlock(i + 2, j + 15, k + 17, Blocks.fence);
    world.setBlock(i + 2, j + 15, k + 18, Blocks.fence);
    world.setBlock(i + 2, j + 15, k + 26, Blocks.stone_stairs, 4, 0);
    world.setBlock(i + 2, j + 16, k + 13, Blocks.cobblestone);
    world.setBlock(i + 2, j + 16, k + 14, Blocks.cobblestone);
    world.setBlock(i + 2, j + 16, k + 15, Blocks.cobblestone);
    world.setBlock(i + 2, j + 16, k + 16, Blocks.cobblestone);
    world.setBlock(i + 2, j + 16, k + 17, Blocks.cobblestone);
    world.setBlock(i + 2, j + 16, k + 18, Blocks.cobblestone);
    world.setBlock(i + 2, j + 16, k + 19, Blocks.cobblestone);
    world.setBlock(i + 2, j + 16, k + 20, Blocks.cobblestone);
    world.setBlock(i + 2, j + 16, k + 21, Blocks.cobblestone);
    world.setBlock(i + 2, j + 16, k + 22, Blocks.cobblestone);
    world.setBlock(i + 2, j + 16, k + 23, Blocks.cobblestone);
    world.setBlock(i + 2, j + 16, k + 24, Blocks.cobblestone);
    world.setBlock(i + 2, j + 16, k + 25, Blocks.cobblestone);
    world.setBlock(i + 2, j + 16, k + 26, Blocks.cobblestone);
    world.setBlock(i + 2, j + 16, k + 27, Blocks.cobblestone);
    world.setBlock(i + 2, j + 17, k + 13, Blocks.planks, 2, 0);
    world.setBlock(i + 2, j + 17, k + 16, Blocks.fence);
    world.setBlock(i + 2, j + 17, k + 17, Blocks.fence);
    world.setBlock(i + 2, j + 17, k + 18, Blocks.fence);
    world.setBlock(i + 2, j + 17, k + 19, Blocks.fence);
    world.setBlock(i + 2, j + 17, k + 20, Blocks.fence);
    world.setBlock(i + 2, j + 17, k + 21, Blocks.fence);
    world.setBlock(i + 2, j + 17, k + 22, Blocks.fence);
    world.setBlock(i + 2, j + 17, k + 23, Blocks.fence);
    world.setBlock(i + 2, j + 17, k + 24, Blocks.fence);
    world.setBlock(i + 2, j + 17, k + 27, Blocks.planks, 2, 0);
    world.setBlock(i + 2, j + 18, k + 13, Blocks.glass_pane);
    world.setBlock(i + 2, j + 18, k + 22, Blocks.fence);
    world.setBlock(i + 2, j + 18, k + 23, Blocks.fence);
    world.setBlock(i + 2, j + 18, k + 24, Blocks.fence);
    world.setBlock(i + 2, j + 18, k + 27, Blocks.glass_pane);
    world.setBlock(i + 2, j + 19, k + 13, Blocks.glass_pane);
    world.setBlock(i + 2, j + 19, k + 21, Blocks.fence);
    world.setBlock(i + 2, j + 19, k + 22, Blocks.fence);
    world.setBlock(i + 2, j + 19, k + 23, Blocks.fence);
    world.setBlock(i + 2, j + 19, k + 27, Blocks.glass_pane);
    world.setBlock(i + 2, j + 20, k + 13, Blocks.planks, 2, 0);
    world.setBlock(i + 2, j + 20, k + 20, Blocks.fence);
    world.setBlock(i + 2, j + 20, k + 21, Blocks.fence);
    world.setBlock(i + 2, j + 20, k + 22, Blocks.fence);
    world.setBlock(i + 2, j + 20, k + 27, Blocks.planks, 2, 0);
    world.setBlock(i + 2, j + 21, k + 13, Blocks.glass_pane);
    world.setBlock(i + 2, j + 21, k + 19, Blocks.fence);
    world.setBlock(i + 2, j + 21, k + 20, Blocks.fence);
    world.setBlock(i + 2, j + 21, k + 21, Blocks.fence);
    world.setBlock(i + 2, j + 21, k + 27, Blocks.glass_pane);
    world.setBlock(i + 2, j + 22, k + 13, Blocks.glass_pane);
    world.setBlock(i + 2, j + 22, k + 18, Blocks.fence);
    world.setBlock(i + 2, j + 22, k + 19, Blocks.fence);
    world.setBlock(i + 2, j + 22, k + 20, Blocks.fence);
    world.setBlock(i + 2, j + 22, k + 27, Blocks.glass_pane);
    world.setBlock(i + 2, j + 23, k + 13, Blocks.stone_stairs, 4, 0);
    world.setBlock(i + 2, j + 23, k + 17, Blocks.fence);
    world.setBlock(i + 2, j + 23, k + 18, Blocks.fence);
    world.setBlock(i + 2, j + 23, k + 19, Blocks.fence);
    world.setBlock(i + 2, j + 23, k + 27, Blocks.stone_stairs, 4, 0);
    world.setBlock(i + 2, j + 24, k + 13, Blocks.cobblestone);
    world.setBlock(i + 2, j + 24, k + 14, Blocks.cobblestone);
    world.setBlock(i + 2, j + 24, k + 15, Blocks.cobblestone);
    world.setBlock(i + 2, j + 24, k + 16, Blocks.cobblestone);
    world.setBlock(i + 2, j + 24, k + 17, Blocks.cobblestone);
    world.setBlock(i + 2, j + 24, k + 18, Blocks.cobblestone);
    world.setBlock(i + 2, j + 24, k + 19, Blocks.cobblestone);
    world.setBlock(i + 2, j + 24, k + 20, Blocks.cobblestone);
    world.setBlock(i + 2, j + 24, k + 21, Blocks.cobblestone);
    world.setBlock(i + 2, j + 24, k + 22, Blocks.cobblestone);
    world.setBlock(i + 2, j + 24, k + 23, Blocks.cobblestone);
    world.setBlock(i + 2, j + 24, k + 24, Blocks.cobblestone);
    world.setBlock(i + 2, j + 24, k + 25, Blocks.cobblestone);
    world.setBlock(i + 2, j + 24, k + 26, Blocks.cobblestone);
    world.setBlock(i + 2, j + 24, k + 27, Blocks.cobblestone);
    world.setBlock(i + 2, j + 24, k + 28, Blocks.cobblestone);
    world.setBlock(i + 2, j + 25, k + 13, Blocks.planks, 3, 0);
    world.setBlock(i + 2, j + 25, k + 17, Blocks.fence);
    world.setBlock(i + 2, j + 25, k + 18, Blocks.fence);
    world.setBlock(i + 2, j + 25, k + 19, Blocks.fence);
    world.setBlock(i + 2, j + 25, k + 20, Blocks.fence);
    world.setBlock(i + 2, j + 25, k + 21, Blocks.fence);
    world.setBlock(i + 2, j + 25, k + 22, Blocks.fence);
    world.setBlock(i + 2, j + 25, k + 23, Blocks.fence);
    world.setBlock(i + 2, j + 25, k + 24, Blocks.fence);
    world.setBlock(i + 2, j + 25, k + 28, Blocks.planks, 3, 0);
    world.setBlock(i + 2, j + 26, k + 14, Blocks.planks, 3, 0);
    world.setBlock(i + 2, j + 26, k + 22, Blocks.fence);
    world.setBlock(i + 2, j + 26, k + 23, Blocks.fence);
    world.setBlock(i + 2, j + 26, k + 24, Blocks.fence);
    world.setBlock(i + 2, j + 26, k + 27, Blocks.planks, 3, 0);
    world.setBlock(i + 2, j + 27, k + 14, Blocks.planks, 3, 0);
    world.setBlock(i + 2, j + 27, k + 21, Blocks.fence);
    world.setBlock(i + 2, j + 27, k + 22, Blocks.fence);
    world.setBlock(i + 2, j + 27, k + 23, Blocks.fence);
    world.setBlock(i + 2, j + 27, k + 27, Blocks.planks, 3, 0);
    world.setBlock(i + 2, j + 28, k + 15, Blocks.planks, 3, 0);
    world.setBlock(i + 2, j + 28, k + 19, Blocks.stone_stairs, 5, 0);
    world.setBlock(i + 2, j + 28, k + 20, Blocks.fence);
    world.setBlock(i + 2, j + 28, k + 21, Blocks.fence);
    world.setBlock(i + 2, j + 28, k + 22, Blocks.fence);
    world.setBlock(i + 2, j + 28, k + 26, Blocks.planks, 3, 0);
    world.setBlock(i + 2, j + 29, k + 15, Blocks.planks, 3, 0);
    world.setBlock(i + 2, j + 29, k + 18, Blocks.fence);
    world.setBlock(i + 2, j + 29, k + 19, Blocks.cobblestone);
    world.setBlock(i + 2, j + 29, k + 20, Blocks.fence);
    world.setBlock(i + 2, j + 29, k + 21, Blocks.fence);
    world.setBlock(i + 2, j + 29, k + 26, Blocks.planks, 3, 0);
    world.setBlock(i + 2, j + 30, k + 16, Blocks.planks, 3, 0);
    world.setBlock(i + 2, j + 30, k + 18, Blocks.fence);
    world.setBlock(i + 2, j + 30, k + 19, Blocks.birch_stairs);
    world.setBlock(i + 2, j + 30, k + 20, Blocks.fence);
    world.setBlock(i + 2, j + 30, k + 25, Blocks.planks, 3, 0);
    world.setBlock(i + 2, j + 31, k + 16, Blocks.planks, 3, 0);
    world.setBlock(i + 2, j + 31, k + 18, Blocks.fence);
    world.setBlock(i + 2, j + 31, k + 20, Blocks.fence);
    world.setBlock(i + 2, j + 31, k + 25, Blocks.planks, 3, 0);
    world.setBlock(i + 2, j + 32, k + 17, Blocks.planks, 3, 0);
    world.setBlock(i + 2, j + 32, k + 24, Blocks.planks, 3, 0);
    world.setBlock(i + 2, j + 33, k + 17, Blocks.planks, 3, 0);
    world.setBlock(i + 2, j + 33, k + 24, Blocks.planks, 3, 0);
    world.setBlock(i + 2, j + 34, k + 18, Blocks.planks, 3, 0);
    world.setBlock(i + 2, j + 34, k + 23, Blocks.planks, 3, 0);
    world.setBlock(i + 2, j + 35, k + 18, Blocks.planks, 3, 0);
    world.setBlock(i + 2, j + 35, k + 23, Blocks.planks, 3, 0);
    world.setBlock(i + 2, j + 36, k + 19, Blocks.planks, 3, 0);
    world.setBlock(i + 2, j + 36, k + 20, Blocks.planks, 3, 0);
    world.setBlock(i + 2, j + 36, k + 21, Blocks.planks, 3, 0);
    world.setBlock(i + 2, j + 36, k + 22, Blocks.planks, 3, 0);
    world.setBlock(i + 2, j + 37, k + 19, Blocks.planks, 3, 0);
    world.setBlock(i + 2, j + 37, k + 20, Blocks.planks, 3, 0);
    world.setBlock(i + 2, j + 37, k + 21, Blocks.planks, 3, 0);
    world.setBlock(i + 2, j + 37, k + 22, Blocks.planks, 3, 0);
    world.setBlock(i + 3, j + 0, k + 0, Blocks.grass);
    world.setBlock(i + 3, j + 0, k + 1, Blocks.grass);
    world.setBlock(i + 3, j + 0, k + 2, Blocks.grass);
    world.setBlock(i + 3, j + 0, k + 3, Blocks.dirt);
    world.setBlock(i + 3, j + 0, k + 4, Blocks.grass);
    world.setBlock(i + 3, j + 0, k + 5, Blocks.planks, 2, 0);
    world.setBlock(i + 3, j + 0, k + 6, Blocks.farmland, 7, 0);
    world.setBlock(i + 3, j + 0, k + 7, Blocks.farmland, 7, 0);
    world.setBlock(i + 3, j + 0, k + 9, Blocks.farmland, 7, 0);
    world.setBlock(i + 3, j + 0, k + 10, Blocks.farmland, 7, 0);
    world.setBlock(i + 3, j + 0, k + 11, Blocks.planks, 2, 0);
    world.setBlock(i + 3, j + 0, k + 12, Blocks.grass);
    world.setBlock(i + 3, j + 0, k + 13, Blocks.dirt);
    world.setBlock(i + 3, j + 0, k + 14, Blocks.planks, 2, 0);
    world.setBlock(i + 3, j + 0, k + 15, Blocks.planks, 2, 0);
    world.setBlock(i + 3, j + 0, k + 16, Blocks.planks, 2, 0);
    world.setBlock(i + 3, j + 0, k + 17, Blocks.planks, 2, 0);
    world.setBlock(i + 3, j + 0, k + 18, Blocks.planks, 2, 0);
    world.setBlock(i + 3, j + 0, k + 19, Blocks.planks, 2, 0);
    world.setBlock(i + 3, j + 0, k + 20, Blocks.planks, 2, 0);
    world.setBlock(i + 3, j + 0, k + 21, Blocks.planks, 2, 0);
    world.setBlock(i + 3, j + 0, k + 22, Blocks.planks, 2, 0);
    world.setBlock(i + 3, j + 0, k + 23, Blocks.planks, 2, 0);
    world.setBlock(i + 3, j + 0, k + 24, Blocks.planks, 2, 0);
    world.setBlock(i + 3, j + 0, k + 25, Blocks.dirt);
    world.setBlock(i + 3, j + 0, k + 26, Blocks.grass);
    world.setBlock(i + 3, j + 0, k + 27, Blocks.grass);
    world.setBlock(i + 3, j + 0, k + 28, Blocks.stonebrick);
    world.setBlock(i + 3, j + 1, k + 0, Blocks.fence);
    world.setBlock(i + 3, j + 1, k + 3, Blocks.pumpkin);
    world.setBlock(i + 3, j + 1, k + 6, Blocks.carrots, 7, 0);
    world.setBlock(i + 3, j + 1, k + 7, Blocks.carrots, 3, 0);
    world.setBlock(i + 3, j + 1, k + 9, Blocks.potatoes, 7, 0);
    world.setBlock(i + 3, j + 1, k + 10, Blocks.potatoes, 7, 0);
    world.setBlock(i + 3, j + 1, k + 13, Blocks.cobblestone);
    world.setBlock(i + 3, j + 1, k + 25, Blocks.cobblestone);
    world.setBlock(i + 3, j + 1, k + 26, Blocks.leaves, 5, 0);
    world.setBlock(i + 3, j + 2, k + 13, Blocks.cobblestone);
    world.setBlock(i + 3, j + 2, k + 25, Blocks.cobblestone);
    world.setBlock(i + 3, j + 3, k + 13, Blocks.cobblestone);
    world.setBlock(i + 3, j + 3, k + 25, Blocks.cobblestone);
    world.setBlock(i + 3, j + 4, k + 13, Blocks.cobblestone);
    world.setBlock(i + 3, j + 4, k + 25, Blocks.cobblestone);
    world.setBlock(i + 3, j + 5, k + 13, Blocks.cobblestone);
    world.setBlock(i + 3, j + 5, k + 25, Blocks.cobblestone);
    world.setBlock(i + 3, j + 6, k + 13, Blocks.cobblestone);
    world.setBlock(i + 3, j + 6, k + 25, Blocks.cobblestone);
    world.setBlock(i + 3, j + 7, k + 13, Blocks.cobblestone);
    world.setBlock(i + 3, j + 7, k + 25, Blocks.cobblestone);
    world.setBlock(i + 3, j + 7, k + 26, Blocks.stone_stairs, 7, 0);
    world.setBlock(i + 3, j + 8, k + 13, Blocks.cobblestone);
    world.setBlock(i + 3, j + 8, k + 14, Blocks.cobblestone);
    world.setBlock(i + 3, j + 8, k + 15, Blocks.cobblestone);
    world.setBlock(i + 3, j + 8, k + 16, Blocks.cobblestone);
    world.setBlock(i + 3, j + 8, k + 17, Blocks.cobblestone);
    world.setBlock(i + 3, j + 8, k + 18, Blocks.cobblestone);
    world.setBlock(i + 3, j + 8, k + 19, Blocks.cobblestone);
    world.setBlock(i + 3, j + 8, k + 20, Blocks.cobblestone);
    world.setBlock(i + 3, j + 8, k + 21, Blocks.cobblestone);
    world.setBlock(i + 3, j + 8, k + 22, Blocks.cobblestone);
    world.setBlock(i + 3, j + 8, k + 23, Blocks.cobblestone);
    world.setBlock(i + 3, j + 8, k + 24, Blocks.cobblestone);
    world.setBlock(i + 3, j + 8, k + 25, Blocks.cobblestone);
    world.setBlock(i + 3, j + 8, k + 26, Blocks.cobblestone);
    world.setBlock(i + 3, j + 9, k + 13, Blocks.cobblestone);
    world.setBlock(i + 3, j + 9, k + 26, Blocks.cobblestone);
    world.setBlock(i + 3, j + 10, k + 13, Blocks.cobblestone);
    world.setBlock(i + 3, j + 10, k + 26, Blocks.cobblestone);
    world.setBlock(i + 3, j + 11, k + 13, Blocks.cobblestone);
    world.setBlock(i + 3, j + 11, k + 26, Blocks.cobblestone);
    world.setBlock(i + 3, j + 12, k + 13, Blocks.cobblestone);
    world.setBlock(i + 3, j + 12, k + 26, Blocks.cobblestone);
    world.setBlock(i + 3, j + 13, k + 13, Blocks.cobblestone);
    world.setBlock(i + 3, j + 13, k + 26, Blocks.cobblestone);
    world.setBlock(i + 3, j + 14, k + 13, Blocks.cobblestone);
    world.setBlock(i + 3, j + 14, k + 26, Blocks.cobblestone);
    world.setBlock(i + 3, j + 15, k + 13, Blocks.cobblestone);
    world.setBlock(i + 3, j + 15, k + 26, Blocks.cobblestone);
    world.setBlock(i + 3, j + 15, k + 27, Blocks.stone_stairs, 7, 0);
    world.setBlock(i + 3, j + 16, k + 13, Blocks.cobblestone);
    world.setBlock(i + 3, j + 16, k + 14, Blocks.cobblestone);
    world.setBlock(i + 3, j + 16, k + 15, Blocks.cobblestone);
    world.setBlock(i + 3, j + 16, k + 16, Blocks.cobblestone);
    world.setBlock(i + 3, j + 16, k + 17, Blocks.cobblestone);
    world.setBlock(i + 3, j + 16, k + 18, Blocks.cobblestone);
    world.setBlock(i + 3, j + 16, k + 19, Blocks.cobblestone);
    world.setBlock(i + 3, j + 16, k + 20, Blocks.cobblestone);
    world.setBlock(i + 3, j + 16, k + 21, Blocks.cobblestone);
    world.setBlock(i + 3, j + 16, k + 22, Blocks.cobblestone);
    world.setBlock(i + 3, j + 16, k + 23, Blocks.cobblestone);
    world.setBlock(i + 3, j + 16, k + 24, Blocks.cobblestone);
    world.setBlock(i + 3, j + 16, k + 25, Blocks.cobblestone);
    world.setBlock(i + 3, j + 16, k + 26, Blocks.cobblestone);
    world.setBlock(i + 3, j + 16, k + 27, Blocks.cobblestone);
    world.setBlock(i + 3, j + 17, k + 13, Blocks.cobblestone);
    world.setBlock(i + 3, j + 17, k + 27, Blocks.cobblestone);
    world.setBlock(i + 3, j + 18, k + 13, Blocks.cobblestone);
    world.setBlock(i + 3, j + 18, k + 27, Blocks.cobblestone);
    world.setBlock(i + 3, j + 19, k + 13, Blocks.cobblestone);
    world.setBlock(i + 3, j + 19, k + 27, Blocks.cobblestone);
    world.setBlock(i + 3, j + 20, k + 13, Blocks.cobblestone);
    world.setBlock(i + 3, j + 20, k + 27, Blocks.cobblestone);
    world.setBlock(i + 3, j + 21, k + 13, Blocks.cobblestone);
    world.setBlock(i + 3, j + 21, k + 27, Blocks.cobblestone);
    world.setBlock(i + 3, j + 22, k + 13, Blocks.cobblestone);
    world.setBlock(i + 3, j + 22, k + 27, Blocks.cobblestone);
    world.setBlock(i + 3, j + 23, k + 13, Blocks.cobblestone);
    world.setBlock(i + 3, j + 23, k + 27, Blocks.cobblestone);
    world.setBlock(i + 3, j + 23, k + 28, Blocks.stone_stairs, 7, 0);
    world.setBlock(i + 3, j + 24, k + 13, Blocks.cobblestone);
    world.setBlock(i + 3, j + 24, k + 14, Blocks.cobblestone);
    world.setBlock(i + 3, j + 24, k + 15, Blocks.cobblestone);
    world.setBlock(i + 3, j + 24, k + 16, Blocks.cobblestone);
    world.setBlock(i + 3, j + 24, k + 17, Blocks.cobblestone);
    world.setBlock(i + 3, j + 24, k + 18, Blocks.cobblestone);
    world.setBlock(i + 3, j + 24, k + 19, Blocks.cobblestone);
    world.setBlock(i + 3, j + 24, k + 20, Blocks.cobblestone);
    world.setBlock(i + 3, j + 24, k + 21, Blocks.cobblestone);
    world.setBlock(i + 3, j + 24, k + 22, Blocks.cobblestone);
    world.setBlock(i + 3, j + 24, k + 23, Blocks.cobblestone);
    world.setBlock(i + 3, j + 24, k + 24, Blocks.cobblestone);
    world.setBlock(i + 3, j + 24, k + 25, Blocks.cobblestone);
    world.setBlock(i + 3, j + 24, k + 26, Blocks.cobblestone);
    world.setBlock(i + 3, j + 24, k + 27, Blocks.cobblestone);
    world.setBlock(i + 3, j + 24, k + 28, Blocks.cobblestone);
    world.setBlock(i + 3, j + 25, k + 13, Blocks.planks, 3, 0);
    world.setBlock(i + 3, j + 25, k + 28, Blocks.cobblestone);
    world.setBlock(i + 3, j + 26, k + 14, Blocks.planks, 3, 0);
    world.setBlock(i + 3, j + 26, k + 27, Blocks.cobblestone);
    world.setBlock(i + 3, j + 26, k + 28, Blocks.cobblestone);
    world.setBlock(i + 3, j + 27, k + 14, Blocks.planks, 3, 0);
    world.setBlock(i + 3, j + 27, k + 27, Blocks.cobblestone);
    world.setBlock(i + 3, j + 27, k + 28, Blocks.cobblestone);
    world.setBlock(i + 3, j + 28, k + 15, Blocks.planks, 3, 0);
    world.setBlock(i + 3, j + 28, k + 26, Blocks.cobblestone);
    world.setBlock(i + 3, j + 28, k + 27, Blocks.cobblestone);
    world.setBlock(i + 3, j + 28, k + 28, Blocks.cobblestone);
    world.setBlock(i + 3, j + 29, k + 15, Blocks.planks, 3, 0);
    world.setBlock(i + 3, j + 29, k + 19, Blocks.stone_stairs, 5, 0);
    world.setBlock(i + 3, j + 29, k + 26, Blocks.cobblestone);
    world.setBlock(i + 3, j + 29, k + 27, Blocks.cobblestone);
    world.setBlock(i + 3, j + 29, k + 28, Blocks.cobblestone);
    world.setBlock(i + 3, j + 30, k + 16, Blocks.planks, 3, 0);
    world.setBlock(i + 3, j + 30, k + 18, Blocks.fence);
    world.setBlock(i + 3, j + 30, k + 19, Blocks.cobblestone);
    world.setBlock(i + 3, j + 30, k + 20, Blocks.fence);
    world.setBlock(i + 3, j + 30, k + 25, Blocks.cobblestone);
    world.setBlock(i + 3, j + 30, k + 26, Blocks.cobblestone);
    world.setBlock(i + 3, j + 30, k + 27, Blocks.cobblestone);
    world.setBlock(i + 3, j + 30, k + 28, Blocks.cobblestone);
    world.setBlock(i + 3, j + 31, k + 16, Blocks.planks, 3, 0);
    world.setBlock(i + 3, j + 31, k + 18, Blocks.fence);
    world.setBlock(i + 3, j + 31, k + 19, Blocks.birch_stairs);
    world.setBlock(i + 3, j + 31, k + 20, Blocks.fence);
    world.setBlock(i + 3, j + 31, k + 25, Blocks.planks, 3, 0);
    world.setBlock(i + 3, j + 31, k + 26, Blocks.planks, 3, 0);
    world.setBlock(i + 3, j + 31, k + 27, Blocks.planks, 3, 0);
    world.setBlock(i + 3, j + 31, k + 28, Blocks.cobblestone);
    world.setBlock(i + 3, j + 32, k + 17, Blocks.planks, 3, 0);
    world.setBlock(i + 3, j + 32, k + 18, Blocks.cobblestone);
    world.setBlock(i + 3, j + 32, k + 20, Blocks.cobblestone);
    world.setBlock(i + 3, j + 32, k + 21, Blocks.cobblestone);
    world.setBlock(i + 3, j + 32, k + 22, Blocks.cobblestone);
    world.setBlock(i + 3, j + 32, k + 23, Blocks.cobblestone);
    world.setBlock(i + 3, j + 32, k + 24, Blocks.planks, 3, 0);
    world.setBlock(i + 3, j + 32, k + 28, Blocks.cobblestone);
    world.setBlock(i + 3, j + 33, k + 17, Blocks.planks, 3, 0);
    world.setBlock(i + 3, j + 33, k + 18, Blocks.fence);
    world.setBlock(i + 3, j + 33, k + 20, Blocks.fence);
    world.setBlock(i + 3, j + 33, k + 21, Blocks.fence);
    world.setBlock(i + 3, j + 33, k + 22, Blocks.fence);
    world.setBlock(i + 3, j + 33, k + 23, Blocks.fence);
    world.setBlock(i + 3, j + 33, k + 24, Blocks.planks, 3, 0);
    world.setBlock(i + 3, j + 33, k + 28, Blocks.stone_stairs, 3, 0);
    world.setBlock(i + 3, j + 34, k + 18, Blocks.planks, 3, 0);
    world.setBlock(i + 3, j + 34, k + 23, Blocks.planks, 3, 0);
    world.setBlock(i + 3, j + 35, k + 18, Blocks.planks, 3, 0);
    world.setBlock(i + 3, j + 35, k + 23, Blocks.planks, 3, 0);
    world.setBlock(i + 3, j + 36, k + 19, Blocks.planks, 3, 0);
    world.setBlock(i + 3, j + 36, k + 22, Blocks.planks, 3, 0);
    world.setBlock(i + 3, j + 37, k + 19, Blocks.planks, 3, 0);
    world.setBlock(i + 3, j + 37, k + 22, Blocks.planks, 3, 0);
    world.setBlock(i + 3, j + 38, k + 20, Blocks.planks, 3, 0);
    world.setBlock(i + 3, j + 38, k + 21, Blocks.planks, 3, 0);
    world.setBlock(i + 3, j + 39, k + 20, Blocks.planks, 3, 0);
    world.setBlock(i + 3, j + 39, k + 21, Blocks.planks, 3, 0);
    world.setBlock(i + 4, j + 0, k + 0, Blocks.grass);
    world.setBlock(i + 4, j + 0, k + 1, Blocks.farmland, 7, 0);
    world.setBlock(i + 4, j + 0, k + 2, Blocks.farmland, 7, 0);
    world.setBlock(i + 4, j + 0, k + 3, Blocks.farmland, 7, 0);
    world.setBlock(i + 4, j + 0, k + 4, Blocks.farmland, 7, 0);
    world.setBlock(i + 4, j + 0, k + 5, Blocks.planks, 2, 0);
    world.setBlock(i + 4, j + 0, k + 6, Blocks.farmland, 7, 0);
    world.setBlock(i + 4, j + 0, k + 7, Blocks.farmland, 7, 0);
    world.setBlock(i + 4, j + 0, k + 9, Blocks.farmland, 7, 0);
    world.setBlock(i + 4, j + 0, k + 10, Blocks.farmland, 7, 0);
    world.setBlock(i + 4, j + 0, k + 11, Blocks.planks, 2, 0);
    world.setBlock(i + 4, j + 0, k + 12, Blocks.grass);
    world.setBlock(i + 4, j + 0, k + 13, Blocks.dirt);
    world.setBlock(i + 4, j + 0, k + 14, Blocks.planks, 2, 0);
    world.setBlock(i + 4, j + 0, k + 15, Blocks.planks, 2, 0);
    world.setBlock(i + 4, j + 0, k + 16, Blocks.planks, 2, 0);
    world.setBlock(i + 4, j + 0, k + 17, Blocks.planks, 2, 0);
    world.setBlock(i + 4, j + 0, k + 18, Blocks.planks, 2, 0);
    world.setBlock(i + 4, j + 0, k + 19, Blocks.planks, 2, 0);
    world.setBlock(i + 4, j + 0, k + 20, Blocks.planks, 2, 0);
    world.setBlock(i + 4, j + 0, k + 21, Blocks.planks, 2, 0);
    world.setBlock(i + 4, j + 0, k + 22, Blocks.planks, 2, 0);
    world.setBlock(i + 4, j + 0, k + 23, Blocks.planks, 2, 0);
    world.setBlock(i + 4, j + 0, k + 24, Blocks.planks, 2, 0);
    world.setBlock(i + 4, j + 0, k + 25, Blocks.dirt);
    world.setBlock(i + 4, j + 0, k + 26, Blocks.grass);
    world.setBlock(i + 4, j + 0, k + 27, Blocks.grass);
    world.setBlock(i + 4, j + 0, k + 28, Blocks.stonebrick);
    world.setBlock(i + 4, j + 1, k + 0, Blocks.fence);
    world.setBlock(i + 4, j + 1, k + 6, Blocks.carrots, 7, 0);
    world.setBlock(i + 4, j + 1, k + 7, Blocks.carrots, 7, 0);
    world.setBlock(i + 4, j + 1, k + 9, Blocks.potatoes, 7, 0);
    world.setBlock(i + 4, j + 1, k + 10, Blocks.potatoes, 7, 0);
    world.setBlock(i + 4, j + 1, k + 13, Blocks.planks, 2, 0);
    world.setBlock(i + 4, j + 1, k + 25, Blocks.planks, 2, 0);
    world.setBlock(i + 4, j + 1, k + 26, Blocks.leaves, 5, 0);
    world.setBlock(i + 4, j + 2, k + 13, Blocks.glass_pane);
    world.setBlock(i + 4, j + 2, k + 25, Blocks.iron_bars);
    world.setBlock(i + 4, j + 3, k + 13, Blocks.glass_pane);
    world.setBlock(i + 4, j + 3, k + 25, Blocks.iron_bars);
    world.setBlock(i + 4, j + 4, k + 13, Blocks.planks, 2, 0);
    world.setBlock(i + 4, j + 4, k + 25, Blocks.planks, 2, 0);
    world.setBlock(i + 4, j + 5, k + 13, Blocks.glass_pane);
    world.setBlock(i + 4, j + 5, k + 25, Blocks.iron_bars);
    world.setBlock(i + 4, j + 6, k + 13, Blocks.glass_pane);
    world.setBlock(i + 4, j + 6, k + 25, Blocks.iron_bars);
    world.setBlock(i + 4, j + 7, k + 13, Blocks.stone_stairs, 5, 0);
    world.setBlock(i + 4, j + 7, k + 25, Blocks.stone_stairs, 5, 0);
    world.setBlock(i + 4, j + 8, k + 13, Blocks.cobblestone);
    world.setBlock(i + 4, j + 8, k + 14, Blocks.cobblestone);
    world.setBlock(i + 4, j + 8, k + 15, Blocks.cobblestone);
    world.setBlock(i + 4, j + 8, k + 16, Blocks.cobblestone);
    world.setBlock(i + 4, j + 8, k + 17, Blocks.cobblestone);
    world.setBlock(i + 4, j + 8, k + 18, Blocks.cobblestone);
    world.setBlock(i + 4, j + 8, k + 19, Blocks.cobblestone);
    world.setBlock(i + 4, j + 8, k + 20, Blocks.cobblestone);
    world.setBlock(i + 4, j + 8, k + 21, Blocks.cobblestone);
    world.setBlock(i + 4, j + 8, k + 22, Blocks.cobblestone);
    world.setBlock(i + 4, j + 8, k + 23, Blocks.cobblestone);
    world.setBlock(i + 4, j + 8, k + 24, Blocks.cobblestone);
    world.setBlock(i + 4, j + 8, k + 25, Blocks.cobblestone);
    world.setBlock(i + 4, j + 8, k + 26, Blocks.cobblestone);
    world.setBlock(i + 4, j + 9, k + 13, Blocks.planks, 2, 0);
    world.setBlock(i + 4, j + 9, k + 26, Blocks.planks, 2, 0);
    world.setBlock(i + 4, j + 10, k + 13, Blocks.glass_pane);
    world.setBlock(i + 4, j + 10, k + 26, Blocks.glass_pane);
    world.setBlock(i + 4, j + 11, k + 13, Blocks.glass_pane);
    world.setBlock(i + 4, j + 11, k + 26, Blocks.glass_pane);
    world.setBlock(i + 4, j + 12, k + 13, Blocks.planks, 2, 0);
    world.setBlock(i + 4, j + 12, k + 26, Blocks.planks, 2, 0);
    world.setBlock(i + 4, j + 13, k + 13, Blocks.glass_pane);
    world.setBlock(i + 4, j + 13, k + 26, Blocks.glass_pane);
    world.setBlock(i + 4, j + 14, k + 13, Blocks.glass_pane);
    world.setBlock(i + 4, j + 14, k + 26, Blocks.glass_pane);
    world.setBlock(i + 4, j + 15, k + 13, Blocks.stone_stairs, 5, 0);
    world.setBlock(i + 4, j + 15, k + 26, Blocks.stone_stairs, 5, 0);
    world.setBlock(i + 4, j + 16, k + 13, Blocks.cobblestone);
    world.setBlock(i + 4, j + 16, k + 14, Blocks.cobblestone);
    world.setBlock(i + 4, j + 16, k + 15, Blocks.cobblestone);
    world.setBlock(i + 4, j + 16, k + 16, Blocks.cobblestone);
    world.setBlock(i + 4, j + 16, k + 17, Blocks.cobblestone);
    world.setBlock(i + 4, j + 16, k + 18, Blocks.cobblestone);
    world.setBlock(i + 4, j + 16, k + 19, Blocks.cobblestone);
    world.setBlock(i + 4, j + 16, k + 20, Blocks.cobblestone);
    world.setBlock(i + 4, j + 16, k + 21, Blocks.cobblestone);
    world.setBlock(i + 4, j + 16, k + 22, Blocks.cobblestone);
    world.setBlock(i + 4, j + 16, k + 23, Blocks.cobblestone);
    world.setBlock(i + 4, j + 16, k + 24, Blocks.cobblestone);
    world.setBlock(i + 4, j + 16, k + 25, Blocks.cobblestone);
    world.setBlock(i + 4, j + 16, k + 26, Blocks.cobblestone);
    world.setBlock(i + 4, j + 16, k + 27, Blocks.cobblestone);
    world.setBlock(i + 4, j + 17, k + 13, Blocks.planks, 2, 0);
    world.setBlock(i + 4, j + 17, k + 27, Blocks.planks, 2, 0);
    world.setBlock(i + 4, j + 18, k + 13, Blocks.glass_pane);
    world.setBlock(i + 4, j + 18, k + 27, Blocks.glass_pane);
    world.setBlock(i + 4, j + 19, k + 13, Blocks.glass_pane);
    world.setBlock(i + 4, j + 19, k + 27, Blocks.glass_pane);
    world.setBlock(i + 4, j + 20, k + 13, Blocks.planks, 2, 0);
    world.setBlock(i + 4, j + 20, k + 27, Blocks.planks, 2, 0);
    world.setBlock(i + 4, j + 21, k + 13, Blocks.glass_pane);
    world.setBlock(i + 4, j + 21, k + 27, Blocks.glass_pane);
    world.setBlock(i + 4, j + 22, k + 13, Blocks.glass_pane);
    world.setBlock(i + 4, j + 22, k + 27, Blocks.glass_pane);
    world.setBlock(i + 4, j + 23, k + 13, Blocks.stone_stairs, 5, 0);
    world.setBlock(i + 4, j + 23, k + 27, Blocks.stone_stairs, 5, 0);
    world.setBlock(i + 4, j + 24, k + 13, Blocks.cobblestone);
    world.setBlock(i + 4, j + 24, k + 14, Blocks.cobblestone);
    world.setBlock(i + 4, j + 24, k + 15, Blocks.cobblestone);
    world.setBlock(i + 4, j + 24, k + 16, Blocks.cobblestone);
    world.setBlock(i + 4, j + 24, k + 17, Blocks.cobblestone);
    world.setBlock(i + 4, j + 24, k + 18, Blocks.cobblestone);
    world.setBlock(i + 4, j + 24, k + 19, Blocks.cobblestone);
    world.setBlock(i + 4, j + 24, k + 20, Blocks.cobblestone);
    world.setBlock(i + 4, j + 24, k + 21, Blocks.cobblestone);
    world.setBlock(i + 4, j + 24, k + 22, Blocks.cobblestone);
    world.setBlock(i + 4, j + 24, k + 23, Blocks.cobblestone);
    world.setBlock(i + 4, j + 24, k + 24, Blocks.cobblestone);
    world.setBlock(i + 4, j + 24, k + 25, Blocks.cobblestone);
    world.setBlock(i + 4, j + 24, k + 26, Blocks.cobblestone);
    world.setBlock(i + 4, j + 24, k + 27, Blocks.cobblestone);
    world.setBlock(i + 4, j + 24, k + 28, Blocks.cobblestone);
    world.setBlock(i + 4, j + 25, k + 13, Blocks.planks, 3, 0);
    world.setBlock(i + 4, j + 25, k + 28, Blocks.planks, 2, 0);
    world.setBlock(i + 4, j + 26, k + 14, Blocks.planks, 3, 0);
    world.setBlock(i + 4, j + 26, k + 28, Blocks.glass_pane);
    world.setBlock(i + 4, j + 27, k + 14, Blocks.planks, 3, 0);
    world.setBlock(i + 4, j + 27, k + 28, Blocks.glass_pane);
    world.setBlock(i + 4, j + 28, k + 15, Blocks.planks, 3, 0);
    world.setBlock(i + 4, j + 28, k + 28, Blocks.planks, 2, 0);
    world.setBlock(i + 4, j + 29, k + 15, Blocks.planks, 3, 0);
    world.setBlock(i + 4, j + 29, k + 28, Blocks.glass_pane);
    world.setBlock(i + 4, j + 30, k + 16, Blocks.planks, 3, 0);
    world.setBlock(i + 4, j + 30, k + 19, Blocks.stone_stairs, 5, 0);
    world.setBlock(i + 4, j + 30, k + 28, Blocks.glass_pane);
    world.setBlock(i + 4, j + 31, k + 16, Blocks.planks, 3, 0);
    world.setBlock(i + 4, j + 31, k + 18, Blocks.fence);
    world.setBlock(i + 4, j + 31, k + 19, Blocks.cobblestone);
    world.setBlock(i + 4, j + 31, k + 20, Blocks.fence);
    world.setBlock(i + 4, j + 31, k + 28, Blocks.stone_stairs, 5, 0);
    world.setBlock(i + 4, j + 32, k + 17, Blocks.planks, 3, 0);
    world.setBlock(i + 4, j + 32, k + 18, Blocks.cobblestone);
    world.setBlock(i + 4, j + 32, k + 19, Blocks.birch_stairs);
    world.setBlock(i + 4, j + 32, k + 20, Blocks.cobblestone);
    world.setBlock(i + 4, j + 32, k + 21, Blocks.cobblestone);
    world.setBlock(i + 4, j + 32, k + 22, Blocks.cobblestone);
    world.setBlock(i + 4, j + 32, k + 23, Blocks.cobblestone);
    world.setBlock(i + 4, j + 32, k + 24, Blocks.planks, 3, 0);
    world.setBlock(i + 4, j + 32, k + 25, Blocks.planks, 3, 0);
    world.setBlock(i + 4, j + 32, k + 26, Blocks.planks, 3, 0);
    world.setBlock(i + 4, j + 32, k + 27, Blocks.planks, 3, 0);
    world.setBlock(i + 4, j + 32, k + 28, Blocks.cobblestone);
    world.setBlock(i + 4, j + 33, k + 17, Blocks.planks, 3, 0);
    world.setBlock(i + 4, j + 33, k + 24, Blocks.planks, 3, 0);
    world.setBlock(i + 4, j + 33, k + 25, Blocks.planks, 3, 0);
    world.setBlock(i + 4, j + 33, k + 26, Blocks.planks, 3, 0);
    world.setBlock(i + 4, j + 33, k + 27, Blocks.planks, 3, 0);
    world.setBlock(i + 4, j + 33, k + 28, Blocks.cobblestone);
    world.setBlock(i + 4, j + 34, k + 18, Blocks.planks, 3, 0);
    world.setBlock(i + 4, j + 34, k + 23, Blocks.planks, 3, 0);
    world.setBlock(i + 4, j + 34, k + 28, Blocks.cobblestone);
    world.setBlock(i + 4, j + 35, k + 18, Blocks.planks, 3, 0);
    world.setBlock(i + 4, j + 35, k + 23, Blocks.planks, 3, 0);
    world.setBlock(i + 4, j + 35, k + 28, Blocks.stone_stairs, 3, 0);
    world.setBlock(i + 4, j + 36, k + 19, Blocks.planks, 3, 0);
    world.setBlock(i + 4, j + 36, k + 22, Blocks.planks, 3, 0);
    world.setBlock(i + 4, j + 37, k + 19, Blocks.planks, 3, 0);
    world.setBlock(i + 4, j + 37, k + 22, Blocks.planks, 3, 0);
    world.setBlock(i + 4, j + 38, k + 20, Blocks.planks, 3, 0);
    world.setBlock(i + 4, j + 38, k + 21, Blocks.planks, 3, 0);
    world.setBlock(i + 4, j + 39, k + 20, Blocks.planks, 3, 0);
    world.setBlock(i + 4, j + 39, k + 21, Blocks.planks, 3, 0);
    world.setBlock(i + 5, j + 0, k + 0, Blocks.grass);
    world.setBlock(i + 5, j + 0, k + 5, Blocks.planks, 2, 0);
    world.setBlock(i + 5, j + 0, k + 6, Blocks.farmland, 7, 0);
    world.setBlock(i + 5, j + 0, k + 7, Blocks.farmland, 7, 0);
    world.setBlock(i + 5, j + 0, k + 9, Blocks.farmland, 7, 0);
    world.setBlock(i + 5, j + 0, k + 10, Blocks.farmland, 7, 0);
    world.setBlock(i + 5, j + 0, k + 11, Blocks.planks, 2, 0);
    world.setBlock(i + 5, j + 0, k + 12, Blocks.grass);
    world.setBlock(i + 5, j + 0, k + 13, Blocks.dirt);
    world.setBlock(i + 5, j + 0, k + 14, Blocks.planks, 2, 0);
    world.setBlock(i + 5, j + 0, k + 15, Blocks.planks, 2, 0);
    world.setBlock(i + 5, j + 0, k + 16, Blocks.planks, 2, 0);
    world.setBlock(i + 5, j + 0, k + 17, Blocks.planks, 2, 0);
    world.setBlock(i + 5, j + 0, k + 18, Blocks.planks, 2, 0);
    world.setBlock(i + 5, j + 0, k + 19, Blocks.planks, 2, 0);
    world.setBlock(i + 5, j + 0, k + 20, Blocks.planks, 2, 0);
    world.setBlock(i + 5, j + 0, k + 21, Blocks.planks, 2, 0);
    world.setBlock(i + 5, j + 0, k + 22, Blocks.planks, 2, 0);
    world.setBlock(i + 5, j + 0, k + 23, Blocks.planks, 2, 0);
    world.setBlock(i + 5, j + 0, k + 24, Blocks.planks, 2, 0);
    world.setBlock(i + 5, j + 0, k + 25, Blocks.dirt);
    world.setBlock(i + 5, j + 0, k + 26, Blocks.grass);
    world.setBlock(i + 5, j + 0, k + 27, Blocks.grass);
    world.setBlock(i + 5, j + 0, k + 28, Blocks.stonebrick);
    world.setBlock(i + 5, j + 1, k + 0, Blocks.fence);
    world.setBlock(i + 5, j + 1, k + 6, Blocks.carrots, 7, 0);
    world.setBlock(i + 5, j + 1, k + 7, Blocks.carrots, 5, 0);
    world.setBlock(i + 5, j + 1, k + 9, Blocks.potatoes, 5, 0);
    world.setBlock(i + 5, j + 1, k + 10, Blocks.potatoes, 7, 0);
    world.setBlock(i + 5, j + 1, k + 13, Blocks.planks, 2, 0);
    world.setBlock(i + 5, j + 1, k + 25, Blocks.planks, 2, 0);
    world.setBlock(i + 5, j + 1, k + 26, Blocks.leaves, 5, 0);
    world.setBlock(i + 5, j + 2, k + 13, Blocks.glass_pane);
    world.setBlock(i + 5, j + 2, k + 25, Blocks.iron_bars);
    world.setBlock(i + 5, j + 3, k + 13, Blocks.glass_pane);
    world.setBlock(i + 5, j + 3, k + 25, Blocks.iron_bars);
    world.setBlock(i + 5, j + 4, k + 13, Blocks.planks, 2, 0);
    world.setBlock(i + 5, j + 4, k + 25, Blocks.planks, 2, 0);
    world.setBlock(i + 5, j + 5, k + 13, Blocks.glass_pane);
    world.setBlock(i + 5, j + 5, k + 25, Blocks.iron_bars);
    world.setBlock(i + 5, j + 6, k + 13, Blocks.glass_pane);
    world.setBlock(i + 5, j + 6, k + 25, Blocks.iron_bars);
    world.setBlock(i + 5, j + 7, k + 13, Blocks.stone_stairs, 4, 0);
    world.setBlock(i + 5, j + 7, k + 25, Blocks.stone_stairs, 4, 0);
    world.setBlock(i + 5, j + 8, k + 13, Blocks.cobblestone);
    world.setBlock(i + 5, j + 8, k + 14, Blocks.cobblestone);
    world.setBlock(i + 5, j + 8, k + 15, Blocks.cobblestone);
    world.setBlock(i + 5, j + 8, k + 16, Blocks.cobblestone);
    world.setBlock(i + 5, j + 8, k + 17, Blocks.cobblestone);
    world.setBlock(i + 5, j + 8, k + 18, Blocks.cobblestone);
    world.setBlock(i + 5, j + 8, k + 19, Blocks.cobblestone);
    world.setBlock(i + 5, j + 8, k + 20, Blocks.cobblestone);
    world.setBlock(i + 5, j + 8, k + 21, Blocks.cobblestone);
    world.setBlock(i + 5, j + 8, k + 22, Blocks.cobblestone);
    world.setBlock(i + 5, j + 8, k + 23, Blocks.cobblestone);
    world.setBlock(i + 5, j + 8, k + 24, Blocks.cobblestone);
    world.setBlock(i + 5, j + 8, k + 25, Blocks.cobblestone);
    world.setBlock(i + 5, j + 8, k + 26, Blocks.cobblestone);
    world.setBlock(i + 5, j + 9, k + 13, Blocks.planks, 2, 0);
    world.setBlock(i + 5, j + 9, k + 26, Blocks.planks, 2, 0);
    world.setBlock(i + 5, j + 10, k + 13, Blocks.glass_pane);
    world.setBlock(i + 5, j + 10, k + 26, Blocks.glass_pane);
    world.setBlock(i + 5, j + 11, k + 13, Blocks.glass_pane);
    world.setBlock(i + 5, j + 11, k + 26, Blocks.glass_pane);
    world.setBlock(i + 5, j + 12, k + 13, Blocks.planks, 2, 0);
    world.setBlock(i + 5, j + 12, k + 26, Blocks.planks, 2, 0);
    world.setBlock(i + 5, j + 13, k + 13, Blocks.glass_pane);
    world.setBlock(i + 5, j + 13, k + 26, Blocks.glass_pane);
    world.setBlock(i + 5, j + 14, k + 13, Blocks.glass_pane);
    world.setBlock(i + 5, j + 14, k + 26, Blocks.glass_pane);
    world.setBlock(i + 5, j + 15, k + 13, Blocks.stone_stairs, 4, 0);
    world.setBlock(i + 5, j + 15, k + 26, Blocks.stone_stairs, 4, 0);
    world.setBlock(i + 5, j + 16, k + 13, Blocks.cobblestone);
    world.setBlock(i + 5, j + 16, k + 14, Blocks.cobblestone);
    world.setBlock(i + 5, j + 16, k + 15, Blocks.cobblestone);
    world.setBlock(i + 5, j + 16, k + 16, Blocks.cobblestone);
    world.setBlock(i + 5, j + 16, k + 17, Blocks.cobblestone);
    world.setBlock(i + 5, j + 16, k + 18, Blocks.cobblestone);
    world.setBlock(i + 5, j + 16, k + 19, Blocks.cobblestone);
    world.setBlock(i + 5, j + 16, k + 20, Blocks.cobblestone);
    world.setBlock(i + 5, j + 16, k + 21, Blocks.cobblestone);
    world.setBlock(i + 5, j + 16, k + 22, Blocks.cobblestone);
    world.setBlock(i + 5, j + 16, k + 23, Blocks.cobblestone);
    world.setBlock(i + 5, j + 16, k + 24, Blocks.cobblestone);
    world.setBlock(i + 5, j + 16, k + 25, Blocks.cobblestone);
    world.setBlock(i + 5, j + 16, k + 26, Blocks.cobblestone);
    world.setBlock(i + 5, j + 16, k + 27, Blocks.cobblestone);
    world.setBlock(i + 5, j + 17, k + 13, Blocks.planks, 2, 0);
    world.setBlock(i + 5, j + 17, k + 27, Blocks.planks, 2, 0);
    world.setBlock(i + 5, j + 18, k + 13, Blocks.glass_pane);
    world.setBlock(i + 5, j + 18, k + 27, Blocks.glass_pane);
    world.setBlock(i + 5, j + 19, k + 13, Blocks.glass_pane);
    world.setBlock(i + 5, j + 19, k + 27, Blocks.glass_pane);
    world.setBlock(i + 5, j + 20, k + 13, Blocks.planks, 2, 0);
    world.setBlock(i + 5, j + 20, k + 27, Blocks.planks, 2, 0);
    world.setBlock(i + 5, j + 21, k + 13, Blocks.glass_pane);
    world.setBlock(i + 5, j + 21, k + 27, Blocks.glass_pane);
    world.setBlock(i + 5, j + 22, k + 13, Blocks.glass_pane);
    world.setBlock(i + 5, j + 22, k + 27, Blocks.glass_pane);
    world.setBlock(i + 5, j + 23, k + 13, Blocks.stone_stairs, 4, 0);
    world.setBlock(i + 5, j + 23, k + 27, Blocks.stone_stairs, 4, 0);
    world.setBlock(i + 5, j + 24, k + 13, Blocks.cobblestone);
    world.setBlock(i + 5, j + 24, k + 14, Blocks.cobblestone);
    world.setBlock(i + 5, j + 24, k + 15, Blocks.cobblestone);
    world.setBlock(i + 5, j + 24, k + 16, Blocks.cobblestone);
    world.setBlock(i + 5, j + 24, k + 17, Blocks.cobblestone);
    world.setBlock(i + 5, j + 24, k + 18, Blocks.cobblestone);
    world.setBlock(i + 5, j + 24, k + 19, Blocks.cobblestone);
    world.setBlock(i + 5, j + 24, k + 20, Blocks.cobblestone);
    world.setBlock(i + 5, j + 24, k + 21, Blocks.cobblestone);
    world.setBlock(i + 5, j + 24, k + 22, Blocks.cobblestone);
    world.setBlock(i + 5, j + 24, k + 23, Blocks.cobblestone);
    world.setBlock(i + 5, j + 24, k + 24, Blocks.cobblestone);
    world.setBlock(i + 5, j + 24, k + 25, Blocks.cobblestone);
    world.setBlock(i + 5, j + 24, k + 26, Blocks.cobblestone);
    world.setBlock(i + 5, j + 24, k + 27, Blocks.cobblestone);
    world.setBlock(i + 5, j + 24, k + 28, Blocks.cobblestone);
    world.setBlock(i + 5, j + 25, k + 13, Blocks.planks, 3, 0);
    world.setBlock(i + 5, j + 25, k + 28, Blocks.planks, 2, 0);
    world.setBlock(i + 5, j + 26, k + 14, Blocks.planks, 3, 0);
    world.setBlock(i + 5, j + 26, k + 28, Blocks.glass_pane);
    world.setBlock(i + 5, j + 27, k + 14, Blocks.planks, 3, 0);
    world.setBlock(i + 5, j + 27, k + 28, Blocks.glass_pane);
    world.setBlock(i + 5, j + 28, k + 15, Blocks.planks, 3, 0);
    world.setBlock(i + 5, j + 28, k + 28, Blocks.planks, 2, 0);
    world.setBlock(i + 5, j + 29, k + 15, Blocks.planks, 3, 0);
    world.setBlock(i + 5, j + 29, k + 28, Blocks.glass_pane);
    world.setBlock(i + 5, j + 30, k + 16, Blocks.planks, 3, 0);
    world.setBlock(i + 5, j + 30, k + 28, Blocks.glass_pane);
    world.setBlock(i + 5, j + 31, k + 16, Blocks.planks, 3, 0);
    world.setBlock(i + 5, j + 31, k + 19, Blocks.stone_stairs, 5, 0);
    world.setBlock(i + 5, j + 31, k + 28, Blocks.stone_stairs, 4, 0);
    world.setBlock(i + 5, j + 32, k + 17, Blocks.planks, 3, 0);
    world.setBlock(i + 5, j + 32, k + 18, Blocks.cobblestone);
    world.setBlock(i + 5, j + 32, k + 19, Blocks.cobblestone);
    world.setBlock(i + 5, j + 32, k + 20, Blocks.cobblestone);
    world.setBlock(i + 5, j + 32, k + 21, Blocks.cobblestone);
    world.setBlock(i + 5, j + 32, k + 22, Blocks.cobblestone);
    world.setBlock(i + 5, j + 32, k + 23, Blocks.cobblestone);
    world.setBlock(i + 5, j + 32, k + 24, Blocks.cobblestone);
    world.setBlock(i + 5, j + 32, k + 25, Blocks.cobblestone);
    world.setBlock(i + 5, j + 32, k + 26, Blocks.cobblestone);
    world.setBlock(i + 5, j + 32, k + 27, Blocks.cobblestone);
    world.setBlock(i + 5, j + 32, k + 28, Blocks.cobblestone);
    world.setBlock(i + 5, j + 33, k + 17, Blocks.planks, 3, 0);
    world.setBlock(i + 5, j + 33, k + 28, Blocks.planks, 2, 0);
    world.setBlock(i + 5, j + 34, k + 18, Blocks.planks, 3, 0);
    world.setBlock(i + 5, j + 34, k + 23, Blocks.planks, 3, 0);
    world.setBlock(i + 5, j + 34, k + 24, Blocks.planks, 3, 0);
    world.setBlock(i + 5, j + 34, k + 25, Blocks.planks, 3, 0);
    world.setBlock(i + 5, j + 34, k + 26, Blocks.planks, 3, 0);
    world.setBlock(i + 5, j + 34, k + 27, Blocks.planks, 3, 0);
    world.setBlock(i + 5, j + 34, k + 28, Blocks.planks, 2, 0);
    world.setBlock(i + 5, j + 35, k + 18, Blocks.planks, 3, 0);
    world.setBlock(i + 5, j + 35, k + 23, Blocks.planks, 3, 0);
    world.setBlock(i + 5, j + 35, k + 24, Blocks.planks, 3, 0);
    world.setBlock(i + 5, j + 35, k + 25, Blocks.planks, 3, 0);
    world.setBlock(i + 5, j + 35, k + 26, Blocks.planks, 3, 0);
    world.setBlock(i + 5, j + 35, k + 27, Blocks.planks, 3, 0);
    world.setBlock(i + 5, j + 35, k + 28, Blocks.cobblestone);
    world.setBlock(i + 5, j + 36, k + 19, Blocks.planks, 3, 0);
    world.setBlock(i + 5, j + 36, k + 22, Blocks.planks, 3, 0);
    world.setBlock(i + 5, j + 36, k + 28, Blocks.cobblestone);
    world.setBlock(i + 5, j + 37, k + 19, Blocks.planks, 3, 0);
    world.setBlock(i + 5, j + 37, k + 22, Blocks.planks, 3, 0);
    world.setBlock(i + 5, j + 37, k + 28, Blocks.stone_stairs, 3, 0);
    world.setBlock(i + 5, j + 38, k + 20, Blocks.planks, 3, 0);
    world.setBlock(i + 5, j + 38, k + 21, Blocks.planks, 3, 0);
    world.setBlock(i + 5, j + 39, k + 20, Blocks.planks, 3, 0);
    world.setBlock(i + 5, j + 39, k + 21, Blocks.planks, 3, 0);
    world.setBlock(i + 6, j + 0, k + 0, Blocks.grass);
    world.setBlock(i + 6, j + 0, k + 1, Blocks.farmland, 7, 0);
    world.setBlock(i + 6, j + 0, k + 2, Blocks.farmland, 7, 0);
    world.setBlock(i + 6, j + 0, k + 3, Blocks.farmland, 7, 0);
    world.setBlock(i + 6, j + 0, k + 4, Blocks.farmland, 7, 0);
    world.setBlock(i + 6, j + 0, k + 5, Blocks.planks, 2, 0);
    world.setBlock(i + 6, j + 0, k + 6, Blocks.farmland, 7, 0);
    world.setBlock(i + 6, j + 0, k + 7, Blocks.farmland, 7, 0);
    world.setBlock(i + 6, j + 0, k + 9, Blocks.farmland, 7, 0);
    world.setBlock(i + 6, j + 0, k + 10, Blocks.farmland, 7, 0);
    world.setBlock(i + 6, j + 0, k + 11, Blocks.planks, 2, 0);
    world.setBlock(i + 6, j + 0, k + 12, Blocks.grass);
    world.setBlock(i + 6, j + 0, k + 13, Blocks.dirt);
    world.setBlock(i + 6, j + 0, k + 14, Blocks.planks, 2, 0);
    world.setBlock(i + 6, j + 0, k + 15, Blocks.planks, 2, 0);

    generate2(world, i, j, k, entity);
    return true;
  }

  public boolean generate2(World world, int i, int j, int k, EntityPlayer entity) {
    world.setBlock(i + 6, j + 0, k + 16, Blocks.planks, 2, 0);
    world.setBlock(i + 6, j + 0, k + 17, Blocks.planks, 2, 0);
    world.setBlock(i + 6, j + 0, k + 18, Blocks.planks, 2, 0);
    world.setBlock(i + 6, j + 0, k + 19, Blocks.planks, 2, 0);
    world.setBlock(i + 6, j + 0, k + 20, Blocks.planks, 2, 0);
    world.setBlock(i + 6, j + 0, k + 21, Blocks.planks, 2, 0);
    world.setBlock(i + 6, j + 0, k + 22, Blocks.planks, 2, 0);
    world.setBlock(i + 6, j + 0, k + 23, Blocks.planks, 2, 0);
    world.setBlock(i + 6, j + 0, k + 24, Blocks.planks, 2, 0);
    world.setBlock(i + 6, j + 0, k + 25, Blocks.dirt);
    world.setBlock(i + 6, j + 0, k + 26, Blocks.grass);
    world.setBlock(i + 6, j + 0, k + 27, Blocks.grass);
    world.setBlock(i + 6, j + 0, k + 28, Blocks.stonebrick);
    world.setBlock(i + 6, j + 1, k + 0, Blocks.fence);
    world.setBlock(i + 6, j + 1, k + 6, Blocks.carrots, 7, 0);
    world.setBlock(i + 6, j + 1, k + 7, Blocks.carrots, 7, 0);
    world.setBlock(i + 6, j + 1, k + 9, Blocks.potatoes, 7, 0);
    world.setBlock(i + 6, j + 1, k + 10, Blocks.potatoes, 7, 0);
    world.setBlock(i + 6, j + 1, k + 13, Blocks.cobblestone);
    world.setBlock(i + 6, j + 1, k + 25, Blocks.cobblestone);
    world.setBlock(i + 6, j + 1, k + 26, Blocks.leaves, 13, 0);
    world.setBlock(i + 6, j + 2, k + 13, Blocks.cobblestone);
    world.setBlock(i + 6, j + 2, k + 25, Blocks.cobblestone);
    world.setBlock(i + 6, j + 3, k + 13, Blocks.cobblestone);
    world.setBlock(i + 6, j + 3, k + 25, Blocks.cobblestone);
    world.setBlock(i + 6, j + 4, k + 13, Blocks.cobblestone);
    world.setBlock(i + 6, j + 4, k + 25, Blocks.cobblestone);
    world.setBlock(i + 6, j + 5, k + 13, Blocks.cobblestone);
    world.setBlock(i + 6, j + 5, k + 25, Blocks.cobblestone);
    world.setBlock(i + 6, j + 6, k + 13, Blocks.cobblestone);
    world.setBlock(i + 6, j + 6, k + 25, Blocks.cobblestone);
    world.setBlock(i + 6, j + 6, k + 26, Blocks.stone_stairs, 7, 0);
    world.setBlock(i + 6, j + 7, k + 13, Blocks.cobblestone);
    world.setBlock(i + 6, j + 7, k + 25, Blocks.cobblestone);
    world.setBlock(i + 6, j + 7, k + 26, Blocks.cobblestone);
    world.setBlock(i + 6, j + 7, k + 27, Blocks.stone_stairs, 7, 0);
    world.setBlock(i + 6, j + 8, k + 13, Blocks.cobblestone);
    world.setBlock(i + 6, j + 8, k + 14, Blocks.cobblestone);
    world.setBlock(i + 6, j + 8, k + 15, Blocks.cobblestone);
    world.setBlock(i + 6, j + 8, k + 16, Blocks.cobblestone);
    world.setBlock(i + 6, j + 8, k + 17, Blocks.cobblestone);
    world.setBlock(i + 6, j + 8, k + 18, Blocks.cobblestone);
    world.setBlock(i + 6, j + 8, k + 19, Blocks.cobblestone);
    world.setBlock(i + 6, j + 8, k + 20, Blocks.cobblestone);
    world.setBlock(i + 6, j + 8, k + 21, Blocks.cobblestone);
    world.setBlock(i + 6, j + 8, k + 22, Blocks.cobblestone);
    world.setBlock(i + 6, j + 8, k + 23, Blocks.cobblestone);
    world.setBlock(i + 6, j + 8, k + 24, Blocks.cobblestone);
    world.setBlock(i + 6, j + 8, k + 25, Blocks.cobblestone);
    world.setBlock(i + 6, j + 8, k + 26, Blocks.cobblestone);
    world.setBlock(i + 6, j + 8, k + 27, Blocks.cobblestone);
    world.setBlock(i + 6, j + 9, k + 13, Blocks.cobblestone);
    world.setBlock(i + 6, j + 9, k + 26, Blocks.cobblestone);
    world.setBlock(i + 6, j + 9, k + 27, Blocks.cobblestone);
    world.setBlock(i + 6, j + 10, k + 13, Blocks.cobblestone);
    world.setBlock(i + 6, j + 10, k + 26, Blocks.cobblestone);
    world.setBlock(i + 6, j + 10, k + 27, Blocks.cobblestone);
    world.setBlock(i + 6, j + 11, k + 13, Blocks.cobblestone);
    world.setBlock(i + 6, j + 11, k + 26, Blocks.cobblestone);
